Workbook

Sheet 合并采购清单
A2: Microduck 鸭子用料与制作工具采购清单
A3: 2026-10-13 | HAT-V5（含后续用料记录）+ IMU-TO-DLX-V2
A4: HAT块数 | B4: 1 | C4: IMU块数 | D4: 1 | F4: 器件总数 | H4: =SUM(F9:F54) -> 109
A5: 修改块数可重算用量。单套：HAT 84 个器件 + IMU 25 个器件。
A6: 采购商品由作者确认已实测可用。按列明的商品型号和订单款式购买。
A7: R33按0Ω采购；TH1可使用原村田PRG18BB101MB1RB（100Ω PTC，0603）。原工程属性保留在位号表。
A8: 类别 | B8: 工程型号 / 当前用料 | C8: 封装与关键规格 | D8: HAT单板(个) | E8: IMU单板(个) | F8: 本次需求(个) | G8: HAT位号 | H8: IMU位号 | I8: 订单店铺 | J8: 订单商品链接 | K8: 必须选择的订单款式 | L8: 每拍含量(个) | M8: 按此款式最少拍数 | N8: 工程型号参考链接 | O8: 购买说明
A9: 电容 | B9: CC0603KRX5R9BB105 | C9: 0603；1uF / ±10% / 50V / X5R | D9: 15 | E9: 0 | F9: =D9*$B$4+E9*$D$4 -> 15 | G9: C1, C2, C3, C4, C6, C10, C27, C29, C31, C33, C35, C40, C41, C42, C43 | I9: 深圳市宏宸电子 | J9: =HYPERLINK("https://item.taobao.com/item.htm?id=630712731066","打开订单商品") -> 打开订单商品 | K9: 0603 1uF ±10% X7R;50V | L9: 1 | M9: =ROUNDUP(F9/L9,0) -> 15 | N9: =HYPERLINK("https://www.lcsc.com/product-detail/C128624.html","查看工程型号") -> 查看工程型号 | O9: 实际采购：0603 / 1uF / ±10% / 50V / X7R。
A10: 电容 | B10: C1608X5R1A106KT000E | C10: 0603；10uF / ±10% / 10V / X5R | D10: 5 | E10: 0 | F10: =D10*$B$4+E10*$D$4 -> 5 | G10: C5, C7, C12, C13, C37 | I10: 深圳市宏宸电子 | J10: =HYPERLINK("https://item.taobao.com/item.htm?id=630712731066","打开订单商品") -> 打开订单商品 | K10: 0603 10uF ±10% X5R;10V | L10: 1 | M10: =ROUNDUP(F10/L10,0) -> 5 | N10: =HYPERLINK("https://item.szlcsc.com/77735.html","查看工程型号") -> 查看工程型号 | O10: 实际采购：0603 / 10uF / ±10% / 10V / X5R。
A11: 电容 | B11: 0603CG221J500NT | C11: 0603；220pF / ±5% / 50V / C0G | D11: 2 | E11: 0 | F11: =D11*$B$4+E11*$D$4 -> 2 | G11: C8, C9 | I11: 深圳市宏宸电子 | J11: =HYPERLINK("https://item.taobao.com/item.htm?id=1005108810412","打开订单商品") -> 打开订单商品 | K11: 0603 220pF ±5% NPO/COG;50V;100个 | L11: 100 | M11: =ROUNDUP(F11/L11,0) -> 1 | N11: =HYPERLINK("https://item.szlcsc.com/167743.html","查看工程型号") -> 查看工程型号 | O11: 选 220pF、50V、C0G(NPO)、±5%、0603；同页其他容量分别选购。
A12: 电容 | B12: CC0603KRX7R9BB104 | C12: 0603；100nF / ±10% / 50V / X7R | D12: 13 | E12: 0 | F12: =D12*$B$4+E12*$D$4 -> 13 | G12: C11, C14, C16, C17, C18, C20, C26, C28, C30, C32, C36, C38, C39 | I12: 深圳市宏宸电子 | J12: =HYPERLINK("https://item.taobao.com/item.htm?id=731471380840","打开订单商品") -> 打开订单商品 | K12: 0603 100nF ±10% X7R;50V;100个 | L12: 100 | M12: =ROUNDUP(F12/L12,0) -> 1 | N12: =HYPERLINK("https://item.szlcsc.com/15331.html","查看工程型号") -> 查看工程型号 | O12: 实际采购：0603 / 100nF / ±10% / 50V / X7R。
A13: 电容 | B13: C3216X7R1V106KT000E | C13: 1206；10uF / ±10% / 35V / X7R | D13: 1 | E13: 0 | F13: =D13*$B$4+E13*$D$4 -> 1 | G13: C15 | I13: 深圳市宏宸电子 | J13: =HYPERLINK("https://item.taobao.com/item.htm?id=730407108775","打开订单商品") -> 打开订单商品 | K13: 1206 10UF ±10% X7R;35V | L13: 1 | M13: =ROUNDUP(F13/L13,0) -> 1 | N13: =HYPERLINK("https://item.szlcsc.com/77793.html","查看工程型号") -> 查看工程型号 | O13: C15 使用 1206、10uF、35V、X7R 款式。
A14: 电容 | B14: GRM188R61A226ME15D | C14: 0603；22uF / ±20% / 10V / X5R | D14: 2 | E14: 0 | F14: =D14*$B$4+E14*$D$4 -> 2 | G14: C21, C22 | I14: 优好电子 | J14: =HYPERLINK("https://item.taobao.com/item.htm?id=993202872551","打开订单商品") -> 打开订单商品 | K14: 22UF 226K 10% X5R;10V;0603=100个 | L14: 100 | M14: =ROUNDUP(F14/L14,0) -> 1 | N14: =HYPERLINK("https://item.szlcsc.com/85589.html","查看工程型号") -> 查看工程型号 | O14: 实际采购：0603 / 22uF / ±10% / 10V / X5R。
A15: 电容 | B15: CC0603KRX7R9BB103 | C15: 0603；10nF / ±10% / 50V / X7R | D15: 1 | E15: 0 | F15: =D15*$B$4+E15*$D$4 -> 1 | G15: C34 | I15: 欧贝顿旗舰店 | J15: =HYPERLINK("https://item.taobao.com/item.htm?id=610558214623","打开订单商品") -> 打开订单商品 | K15: 0603 10NF 50V 10% 100个 | L15: 100 | M15: =ROUNDUP(F15/L15,0) -> 1 | N15: =HYPERLINK("https://item.szlcsc.com/101256.html","查看工程型号") -> 查看工程型号 | O15: 实际采购：0603 / 10nF / ±10% / 50V / X7R。
A16: 半导体 | B16: BAT54SW,115 | C16: SOT-323；二极管配置:1对串联式；正向压降(Vf):800mV@100mA；直流反向耐压(Vr):30V；整流电流:200mA | D16: 1 | E16: 0 | F16: =D16*$B$4+E16*$D$4 -> 1 | G16: D1 | I16: 深圳市乐桥微科技 | J16: =HYPERLINK("https://item.taobao.com/item.htm?id=793455311175","打开订单商品") -> 打开订单商品 | K16: BAT54SW 印字44t（20只） | L16: 20 | M16: =ROUNDUP(F16/L16,0) -> 1 | N16: =HYPERLINK("https://item.szlcsc.com/79742.html","查看工程型号") -> 查看工程型号 | O16: 选择 BAT54SW / SOT-323 款式。
A17: 半导体 | B17: BZT52C5V1S-7-F | C17: SOD-323；二极管配置:1个独立式；稳压值(标称值):5.1V；稳压值(范围值):4.8V~5.4V；耗散功率(Pd):200mW | D17: 1 | E17: 0 | F17: =D17*$B$4+E17*$D$4 -> 1 | G17: D4 | I17: 稳泊仕旗舰店 | J17: =HYPERLINK("https://item.taobao.com/item.htm?id=943185002457","打开订单商品") -> 打开订单商品 | K17: BZT52C5V1S W8 SOD-323 (50个) | L17: 50 | M17: =ROUNDUP(F17/L17,0) -> 1 | N17: =HYPERLINK("https://item.szlcsc.com/162688.html","查看工程型号") -> 查看工程型号 | O17: 选择 BZT52C5V1S / 5.1V / SOD-323 款式。
A18: 磁珠 | B18: BLM18KG601SN1D | C18: 0603；±25% / 600Ω@100MHz / 1.3A | D18: 1 | E18: 0 | F18: =D18*$B$4+E18*$D$4 -> 1 | G18: FB1 | I18: 科芯奇旗舰店 | J18: =HYPERLINK("https://item.taobao.com/item.htm?id=931081429973","打开订单商品") -> 打开订单商品 | K18: 0603_600R_1.3A_±25%【100只】 | L18: 100 | M18: =ROUNDUP(F18/L18,0) -> 1 | N18: =HYPERLINK("https://item.szlcsc.com/87009.html","查看工程型号") -> 查看工程型号 | O18: 实际采购：0603 / 600Ω@100MHz / 1.3A / ±25%。
A19: 磁珠 | B19: PE-0603PFB121ST | C19: 0603；±25% / 120Ω@100MHz / 2A | D19: 2 | E19: 0 | F19: =D19*$B$4+E19*$D$4 -> 2 | G19: FB2, FB3 | I19: 科芯奇旗舰店 | J19: =HYPERLINK("https://item.taobao.com/item.htm?id=931081429973","打开订单商品") -> 打开订单商品 | K19: 0603_120R_2A_±25%【100只】 | L19: 100 | M19: =ROUNDUP(F19/L19,0) -> 1 | N19: =HYPERLINK("https://item.szlcsc.com/2753383.html","查看工程型号") -> 查看工程型号 | O19: 实际采购：0603 / 120Ω@100MHz / 2A / ±25%。
A20: 连接器 | B20: B2B-EH-A(LF)(SN) | C20: 插件,P=2.5mm；250V / 3A | D20: 3 | E20: 0 | F20: =D20*$B$4+E20*$D$4 -> 3 | G20: J1, J2, J9 | I20: 启色数码旗舰店 | J20: =HYPERLINK("https://item.taobao.com/item.htm?id=832569969546","打开订单商品") -> 打开订单商品 | K20: EH2.5MM 2P直针座（50个） | L20: 50 | M20: =ROUNDUP(F20/L20,0) -> 1 | N20: =HYPERLINK("https://item.szlcsc.com/171642.html","查看工程型号") -> 查看工程型号 | O20: EH 2P 直针座；按 EH2.5MM 2P 直针座选项购买。
A21: 连接器 | B21: FH-00339 | C21: SMD,P=2.54mm；3A | D21: 1 | E21: 0 | F21: =D21*$B$4+E21*$D$4 -> 1 | G21: J4 | I21: 海雀数码专营店 | J21: =HYPERLINK("https://item.taobao.com/item.htm?id=533725557959","打开订单商品") -> 打开订单商品 | K21: 2*20P 贴片排母【2个】 | L21: 2 | M21: =ROUNDUP(F21/L21,0) -> 1 | N21: =HYPERLINK("https://item.szlcsc.com/2784386.html","查看工程型号") -> 查看工程型号 | O21: 双排 2×20P、2.54mm、贴片排母，安装在 HAT 底面。
A22: 连接器 | B22: BM04B-SRSS-TB(LF)(SN) | C22: SMD,P=1mm；50V / 1A | D22: 1 | E22: 0 | F22: =D22*$B$4+E22*$D$4 -> 1 | G22: J5 | I22: 信容芯旗舰店 | J22: =HYPERLINK("https://item.taobao.com/item.htm?id=920058690376","打开订单商品") -> 打开订单商品 | K22: 4P立贴（15个） | L22: 15 | M22: =ROUNDUP(F22/L22,0) -> 1 | N22: =HYPERLINK("https://item.szlcsc.com/171770.html","查看工程型号") -> 查看工程型号 | O22: SH1.0 / 4P / 立贴，按“4P立贴（15个）”选项购买。
A23: 连接器 | B23: B3B-EH-A(LF)(SN) | C23: 插件,P=2.5mm；250V / 3A | D23: 2 | E23: 1 | F23: =D23*$B$4+E23*$D$4 -> 3 | G23: J13, J14 | H23: J1 | I23: 启色数码旗舰店 | J23: =HYPERLINK("https://item.taobao.com/item.htm?id=832569969546","打开订单商品") -> 打开订单商品 | K23: EH2.5MM 3P直针座（50个） | L23: 50 | M23: =ROUNDUP(F23/L23,0) -> 1 | N23: =HYPERLINK("https://item.szlcsc.com/171639.html","查看工程型号") -> 查看工程型号 | O23: EH 3P 直针座，HAT 两只、IMU 一只。
A24: 电感 | B24: SWPA6045S6R8MT | C24: SMD,6x6mm；6.8uH / ±20% / 3A | D24: 1 | E24: 0 | F24: =D24*$B$4+E24*$D$4 -> 1 | G24: L4 | I24: 迪林旗舰店 | J24: =HYPERLINK("https://item.taobao.com/item.htm?id=598174251748","打开订单商品") -> 打开订单商品 | K24: 合金0630 6.8UH 印6R8 10个 6A 一体 | L24: 10 | M24: =ROUNDUP(F24/L24,0) -> 1 | N24: =HYPERLINK("https://item.szlcsc.com/58286.html","查看工程型号") -> 查看工程型号 | O24: 实际使用：合金0630、6.8uH、6A一体成型电感（订单标称）。
A25: 麦克风 | B25: LMA2718T421-OA5-2 | C25: SMD-4P,2.8x1.9mm；指向性:全指向；信噪比:55dB；灵敏度:-42dB；阻抗:300Ω | D25: 1 | E25: 0 | F25: =D25*$B$4+E25*$D$4 -> 1 | G25: MK1 | I25: 深圳市华源芯电子有限公司 电子元器件配单 | J25: =HYPERLINK("https://item.taobao.com/item.htm?id=996702312391","打开订单商品") -> 打开订单商品 | K25: 2718 上进音 硅麦克风【2个】 | L25: 2 | M25: =ROUNDUP(F25/L25,0) -> 1 | N25: =HYPERLINK("https://item.szlcsc.com/8705873.html","查看工程型号") -> 查看工程型号 | O25: 实际使用：2718 上进音模拟 MEMS 麦克风，按“2718 上进音 硅麦克风【2个】”购买。
A26: 半导体 | B26: MMBT3906 | C26: SOT-23；晶体管类型:PNP；集电极电流(Ic):200mA；集射极击穿电压(Vceo):40V；耗散功率(Pd):200mW；直流电流增益(hFE):100@10mA,1V | D26: 1 | E26: 0 | F26: =D26*$B$4+E26*$D$4 -> 1 | G26: Q1 | I26: 稳泊仕旗舰店 | J26: =HYPERLINK("https://item.taobao.com/item.htm?id=944306254140","打开订单商品") -> 打开订单商品 | K26: MMBT3906 丝印2A SOT-23(50个) | L26: 50 | M26: =ROUNDUP(F26/L26,0) -> 1 | N26: =HYPERLINK("https://item.szlcsc.com/774233.html","查看工程型号") -> 查看工程型号 | O26: 选择 MMBT3906 / PNP / SOT-23 款式。
A27: 半导体 | B27: SI2312CDS-T1-GE3 | C27: SOT-23；数量:1个N沟道；漏源电压(Vdss):20V；连续漏极电流(Id):6A；导通电阻(RDS(on)):41.4mΩ@1.8V,5.6A；耗散功率(Pd):2.1W；阈值电压(Vgs(th)):1V@250uA | D27: 1 | E27: 0 | F27: =D27*$B$4+E27*$D$4 -> 1 | G27: Q2 | I27: 一芯向上电子 | J27: =HYPERLINK("https://item.taobao.com/item.htm?id=909264246006","打开订单商品") -> 打开订单商品 | K27: SI2312DS（AE9T）N沟道（20只） | L27: 20 | M27: =ROUNDUP(F27/L27,0) -> 1 | N27: =HYPERLINK("https://item.szlcsc.com/153849.html","查看工程型号") -> 查看工程型号 | O27: 实际使用：SI2312DS（AE9T）N沟道，20只包装。
A28: 电阻 | B28: RC0603FR-0710KL | C28: 0603；10kΩ / ±1% / ±100ppm/℃ / 100mW | D28: 12 | E28: 3 | F28: =D28*$B$4+E28*$D$4 -> 15 | G28: R1, R2, R6, R12, R13, R22, R23, R26, R27, R29, R31, R32 | H28: R2, R4, R5 | I28: 深圳市永芯泰电子企业店 | J28: =HYPERLINK("https://item.taobao.com/item.htm?id=947267344247","打开订单商品") -> 打开订单商品 | K28: 10K;0603 1%（100个） | L28: 100 | M28: =ROUNDUP(F28/L28,0) -> 1 | N28: =HYPERLINK("https://item.szlcsc.com/99429.html","查看工程型号") -> 查看工程型号 | O28: 10kΩ / ±1% / 0603；HAT 十二只、IMU 三只。
A29: 电阻 | B29: 0603WAF0000T5E | C29: 0603；0Ω / ±1% / 0603 | D29: 5 | E29: 1 | F29: =D29*$B$4+E29*$D$4 -> 6 | G29: R3, R4, R5, R7, R33 | H29: R1 | I29: 深圳市永芯泰电子企业店 | J29: =HYPERLINK("https://item.taobao.com/item.htm?id=947267344247","打开订单商品") -> 打开订单商品 | K29: 0R/0欧;0603 1%（100个） | L29: 100 | M29: =ROUNDUP(F29/L29,0) -> 1 | N29: =HYPERLINK("https://item.szlcsc.com/21903.html","查看工程型号") -> 查看工程型号 | O29: 0Ω / 0603；HAT R33 按后续 0Ω / C21189 补丁计入。
A30: 电阻 | B30: 0603WAF1000T5E | C30: 0603；100Ω / ±1% / ±200ppm/℃ / 100mW | D30: 1 | E30: 0 | F30: =D30*$B$4+E30*$D$4 -> 1 | G30: R8 | I30: 深圳市永芯泰电子企业店 | J30: =HYPERLINK("https://item.taobao.com/item.htm?id=947267344247","打开订单商品") -> 打开订单商品 | K30: 100R/100欧;0603 1%（100个） | L30: 100 | M30: =ROUNDUP(F30/L30,0) -> 1 | N30: =HYPERLINK("https://www.lcsc.com/product-detail/C22775.html","查看工程型号") -> 查看工程型号 | O30: 100Ω / ±1% / 0603，用于 HAT R8。
A31: 电阻 | B31: 0603WAF2002T5E | C31: 0603；20kΩ / ±1% / ±100ppm/℃ / 100mW | D31: 1 | E31: 0 | F31: =D31*$B$4+E31*$D$4 -> 1 | G31: R28 | I31: 深圳市永芯泰电子企业店 | J31: =HYPERLINK("https://item.taobao.com/item.htm?id=947267344247","打开订单商品") -> 打开订单商品 | K31: 20K;0603 1%（100个） | L31: 100 | M31: =ROUNDUP(F31/L31,0) -> 1 | N31: =HYPERLINK("https://item.szlcsc.com/4591.html","查看工程型号") -> 查看工程型号 | O31: 20kΩ / ±1% / 0603。
A32: 热敏电阻 | B32: PRG18BB101MB1RB | C32: 0603；100Ω / PTC / 村田 | D32: 1 | E32: 0 | F32: =D32*$B$4+E32*$D$4 -> 1 | G32: TH1 | I32: 贤辉亿芯 | J32: =HYPERLINK("https://item.taobao.com/item.htm?id=582129955778","打开订单商品") -> 打开订单商品 | K32: 100R PRG18BB101MB1RB | L32: 1 | M32: =ROUNDUP(F32/L32,0) -> 1 | N32: =HYPERLINK("https://item.szlcsc.com/984022.html","查看工程型号") -> 查看工程型号 | O32: TH1可使用原村田PRG18BB101MB1RB（100Ω PTC，0603），按原订单100R款式采购；R33使用0Ω。
A33: 半导体 | B33: PAM8406DR | C33: SOIC-16；功放类型:AB类功放；D类功放；扬声器通道数:双声道；输出功率:5Wx2@2Ω；静态电流(Iq):10mA | D33: 1 | E33: 0 | F33: =D33*$B$4+E33*$D$4 -> 1 | G33: U1 | I33: 深圳市远大芯程科技 | J33: =HYPERLINK("https://item.taobao.com/item.htm?id=808484505787","打开订单商品") -> 打开订单商品 | K33: PAM8406DR | L33: 1 | M33: =ROUNDUP(F33/L33,0) -> 1 | N33: =HYPERLINK("https://item.szlcsc.com/87446.html","查看工程型号") -> 查看工程型号 | O33: 实际使用：PAM8406DR，订单标注 SOP16。
A34: 半导体 | B34: TLV320AIC3104IRHBR | C34: HVQFN-32-EP(5x5)；类型:编解码器；接口类型:I2S；I2C；采样率:8kHz~96kHz | D34: 1 | E34: 0 | F34: =D34*$B$4+E34*$D$4 -> 1 | G34: U2 | I34: 淼鑫电子科技 | J34: =HYPERLINK("https://item.taobao.com/item.htm?id=908248360601","打开订单商品") -> 打开订单商品 | K34: 商品无选项，按商品标题完整型号购买 | L34: 1 | M34: =ROUNDUP(F34/L34,0) -> 1 | N34: =HYPERLINK("https://www.lcsc.com/product-detail/C181753.html","查看工程型号") -> 查看工程型号 | O34: TLV320AIC3104IRHBR，按商品完整型号购买。
A35: 半导体 | B35: XC6206P182MR | C35: SOT-23；输出极性:正极；工作电压:8V；输出电压:1.8V；输出电流:250mA；电源纹波抑制比(PSRR):40dB@(1kHz)；输出类型:固定 | D35: 1 | E35: 0 | F35: =D35*$B$4+E35*$D$4 -> 1 | G35: U3 | I35: 启色数码旗舰店 | J35: =HYPERLINK("https://item.taobao.com/item.htm?id=762173333947","打开订单商品") -> 打开订单商品 | K35: XC6206P182MR 65K5 SOT-23 (20个) | L35: 20 | M35: =ROUNDUP(F35/L35,0) -> 1 | N35: =HYPERLINK("https://item.szlcsc.com/324033.html","查看工程型号") -> 查看工程型号 | O35: XC6206P182MR / 1.8V / SOT-23，20个包装。
A36: 半导体 | B36: SN74LVC1G08DBVR | C36: SOT-23-5；逻辑类型:与门；通道数:1；工作电压:1.65V~5.5V；静态电流(Iq):10uA；传播延迟(tpd):4ns@5V,50pF | D36: 1 | E36: 0 | F36: =D36*$B$4+E36*$D$4 -> 1 | G36: U5 | I36: 深圳市德明电子贸易商城 | J36: =HYPERLINK("https://item.taobao.com/item.htm?id=902117985110","打开订单商品") -> 打开订单商品 | K36: SN74LVC1G08DBVR;5个全国包邮 | L36: 5 | M36: =ROUNDUP(F36/L36,0) -> 1 | N36: =HYPERLINK("https://www.lcsc.com/product-detail/C7666.html","查看工程型号") -> 查看工程型号 | O36: SN74LVC1G08DBVR / SOT-23-5 与门，按同页对应型号选项购买。
A37: 半导体 | B37: SN74LVC1G125DBVR-TP | C37: SOT-23-5；输入类型:-；工作电压:1.65V~5.5V；元件数:1；每个元件位数:-；灌电流(IOL):24mA；拉电流(IOH):24mA | D37: 1 | E37: 0 | F37: =D37*$B$4+E37*$D$4 -> 1 | G37: U6 | I37: 深圳市德明电子贸易商城 | J37: =HYPERLINK("https://item.taobao.com/item.htm?id=902117985110","打开订单商品") -> 打开订单商品 | K37: SN74LVC1G125DBVR;5个全国包邮 | L37: 5 | M37: =ROUNDUP(F37/L37,0) -> 1 | N37: =HYPERLINK("https://item.szlcsc.com/3597950.html","查看工程型号") -> 查看工程型号 | O37: 实际使用：SN74LVC1G125DBVR / SOT-23-5，5个包装。
A38: 半导体 | B38: SN74LVC1G126DBVR | C38: SOT-23-5；输入类型:-；工作电压:1.65V~5.5V；元件数:1；每个元件位数:1；灌电流(IOL):32mA；拉电流(IOH):32mA | D38: 1 | E38: 0 | F38: =D38*$B$4+E38*$D$4 -> 1 | G38: U7 | I38: 深圳市德明电子贸易商城 | J38: =HYPERLINK("https://item.taobao.com/item.htm?id=902117985110","打开订单商品") -> 打开订单商品 | K38: SN74LVC1G126DBVR;5个全国包邮 | L38: 5 | M38: =ROUNDUP(F38/L38,0) -> 1 | N38: =HYPERLINK("https://www.lcsc.com/product-detail/C7834.html","查看工程型号") -> 查看工程型号 | O38: 实际使用：SN74LVC1G126DBVR / SOT-23-5，5个包装。
A39: 半导体 | B39: AP63205WU-7 | C39: TSOT-23-6；功能类型:降压型；工作电压:3.8V~32V；输出电压:5V；输出电流:2A；输出类型:固定 | D39: 1 | E39: 0 | F39: =D39*$B$4+E39*$D$4 -> 1 | G39: U9 | I39: 深圳市远大芯程科技 | J39: =HYPERLINK("https://item.taobao.com/item.htm?id=969642590399","打开订单商品") -> 打开订单商品 | K39: AP63205WU-7 | L39: 1 | M39: =ROUNDUP(F39/L39,0) -> 1 | N39: =HYPERLINK("https://item.szlcsc.com/2162639.html","查看工程型号") -> 查看工程型号 | O39: AP63205WU-7，固定5V降压芯片，按对应完整型号购买。
A40: 半导体 | B40: LM5050MKX-1/NOPB | C40: TSOT-23-6；LM5050-1 5V 至 75V、400uA IQ ORing FET 控制器 | D40: 1 | E40: 0 | F40: =D40*$B$4+E40*$D$4 -> 1 | G40: U10 | I40: 深圳市安芯选电子 | J40: =HYPERLINK("https://item.taobao.com/item.htm?id=1013388982214","打开订单商品") -> 打开订单商品 | K40: SOT-23;LM5050MKX-1/NOPB 原装正品 | L40: 1 | M40: =ROUNDUP(F40/L40,0) -> 1 | N40: =HYPERLINK("https://www.lcsc.com/product-detail/C473393.html","查看工程型号") -> 查看工程型号 | O40: LM5050MKX-1/NOPB，按完整型号购买。
A41: 晶振 | B41: OT3EL89CJI-111YLC-12M | C41: SMD2520-4P；12MHz | D41: 1 | E41: 0 | F41: =D41*$B$4+E41*$D$4 -> 1 | G41: Y1 | I41: 深圳市晶诺源电子 | J41: =HYPERLINK("https://item.taobao.com/item.htm?id=944053669860","打开订单商品") -> 打开订单商品 | K41: 12MHZ 1.2V~3.36V宽压[高精度10PPM];SMD2520-4P CMOS输出 | L41: 1 | M41: =ROUNDUP(F41/L41,0) -> 1 | N41: =HYPERLINK("https://item.szlcsc.com/8414369.html","查看工程型号") -> 查看工程型号 | O41: 实际使用：12MHz、2520-4P、CMOS输出有源晶振，宽压1.2V~3.36V（订单标称）。
...

Sheet HAT位号BOM
A2: HAT 位号 BOM
A3: 源：HAT-V5.epro2 / PCB2；84 个器件，工程原始属性保留。
A4: R33：采购0Ω / C21189，保留原工程属性。TH1可使用原村田PRG18BB101MB1RB，100Ω PTC / 0603。
A5: C8/C9 为 220pF（已修正）；C15 为 1206 / 10uF / 35V。
A6: 器件用量按实际位号统计，采购商品已在作者实机验证可用。
A7: 位号 | B7: 用途 / 位号原文 | C7: 工程完整型号 | D7: 工程立创料号 | E7: 工程封装 | F7: 工程关键参数 | G7: 当前采购规格 / 订单款式 | H7: 订单商品链接 | I7: 工程BOM型号链接 | J7: 用料说明 | K7: 工程来源
A8: C1 | B8: 1uF / left AC coupling | C8: CC0603KRX5R9BB105 | D8: C128624 | E8: 0603 | F8: 1uF / ±10% / 50V / X5R | G8: 0603 1uF ±10% X7R;50V | H8: =HYPERLINK("https://item.taobao.com/item.htm?id=630712731066","打开订单商品") -> 打开订单商品 | I8: =HYPERLINK("https://www.lcsc.com/product-detail/C128624.html","查看工程型号") -> 查看工程型号 | J8: 实际采购：0603 / 1uF / ±10% / 50V / X7R。 | K8: HAT-V5.epro2 / PCB2
A9: C2 | B9: 1uF / right AC coupling | C9: CC0603KRX5R9BB105 | D9: C128624 | E9: 0603 | F9: 1uF / ±10% / 50V / X5R | G9: 0603 1uF ±10% X7R;50V | H9: =HYPERLINK("https://item.taobao.com/item.htm?id=630712731066","打开订单商品") -> 打开订单商品 | I9: =HYPERLINK("https://www.lcsc.com/product-detail/C128624.html","查看工程型号") -> 查看工程型号 | J9: 实际采购：0603 / 1uF / ±10% / 50V / X7R。 | K9: HAT-V5.epro2 / PCB2
A10: C3 | B10: 1uF / VREF | C10: CC0603KRX5R9BB105 | D10: C128624 | E10: 0603 | F10: 1uF / ±10% / 50V / X5R | G10: 0603 1uF ±10% X7R;50V | H10: =HYPERLINK("https://item.taobao.com/item.htm?id=630712731066","打开订单商品") -> 打开订单商品 | I10: =HYPERLINK("https://www.lcsc.com/product-detail/C128624.html","查看工程型号") -> 查看工程型号 | J10: 实际采购：0603 / 1uF / ±10% / 50V / X7R。 | K10: HAT-V5.epro2 / PCB2
A11: C4 | B11: 1uF | C11: CC0603KRX5R9BB105 | D11: C128624 | E11: 0603 | F11: 1uF / ±10% / 50V / X5R | G11: 0603 1uF ±10% X7R;50V | H11: =HYPERLINK("https://item.taobao.com/item.htm?id=630712731066","打开订单商品") -> 打开订单商品 | I11: =HYPERLINK("https://www.lcsc.com/product-detail/C128624.html","查看工程型号") -> 查看工程型号 | J11: 实际采购：0603 / 1uF / ±10% / 50V / X7R。 | K11: HAT-V5.epro2 / PCB2
A12: C5 | B12: 10uF | C12: C1608X5R1A106KT000E | D12: C76608 | E12: 0603 | F12: 10uF / ±10% / 10V / X5R | G12: 0603 10uF ±10% X5R;10V | H12: =HYPERLINK("https://item.taobao.com/item.htm?id=630712731066","打开订单商品") -> 打开订单商品 | I12: =HYPERLINK("https://item.szlcsc.com/77735.html","查看工程型号") -> 查看工程型号 | J12: 实际采购：0603 / 10uF / ±10% / 10V / X5R。 | K12: HAT-V5.epro2 / PCB2
A13: C6 | B13: 1uF | C13: CC0603KRX5R9BB105 | D13: C128624 | E13: 0603 | F13: 1uF / ±10% / 50V / X5R | G13: 0603 1uF ±10% X7R;50V | H13: =HYPERLINK("https://item.taobao.com/item.htm?id=630712731066","打开订单商品") -> 打开订单商品 | I13: =HYPERLINK("https://www.lcsc.com/product-detail/C128624.html","查看工程型号") -> 查看工程型号 | J13: 实际采购：0603 / 1uF / ±10% / 50V / X7R。 | K13: HAT-V5.epro2 / PCB2
A14: C7 | B14: 10uF | C14: C1608X5R1A106KT000E | D14: C76608 | E14: 0603 | F14: 10uF / ±10% / 10V / X5R | G14: 0603 10uF ±10% X5R;10V | H14: =HYPERLINK("https://item.taobao.com/item.htm?id=630712731066","打开订单商品") -> 打开订单商品 | I14: =HYPERLINK("https://item.szlcsc.com/77735.html","查看工程型号") -> 查看工程型号 | J14: 实际采购：0603 / 10uF / ±10% / 10V / X5R。 | K14: HAT-V5.epro2 / PCB2
A15: C8 | B15: 0603CG221J500NT | C15: 0603CG221J500NT | D15: C156398 | E15: 0603 | F15: 220pF / ±5% / 50V / C0G | G15: 0603 220pF ±5% NPO/COG;50V;100个 | H15: =HYPERLINK("https://item.taobao.com/item.htm?id=1005108810412","打开订单商品") -> 打开订单商品 | I15: =HYPERLINK("https://item.szlcsc.com/167743.html","查看工程型号") -> 查看工程型号 | J15: 选 220pF、50V、C0G(NPO)、±5%、0603；同页其他容量分别选购。 | K15: HAT-V5.epro2 / PCB2
A16: C9 | B16: 0603CG221J500NT | C16: 0603CG221J500NT | D16: C156398 | E16: 0603 | F16: 220pF / ±5% / 50V / C0G | G16: 0603 220pF ±5% NPO/COG;50V;100个 | H16: =HYPERLINK("https://item.taobao.com/item.htm?id=1005108810412","打开订单商品") -> 打开订单商品 | I16: =HYPERLINK("https://item.szlcsc.com/167743.html","查看工程型号") -> 查看工程型号 | J16: 选 220pF、50V、C0G(NPO)、±5%、0603；同页其他容量分别选购。 | K16: HAT-V5.epro2 / PCB2
A17: C10 | B17: 1uF / onboard MIC coupling | C17: CC0603KRX5R9BB105 | D17: C128624 | E17: 0603 | F17: 1uF / ±10% / 50V / X5R | G17: 0603 1uF ±10% X7R;50V | H17: =HYPERLINK("https://item.taobao.com/item.htm?id=630712731066","打开订单商品") -> 打开订单商品 | I17: =HYPERLINK("https://www.lcsc.com/product-detail/C128624.html","查看工程型号") -> 查看工程型号 | J17: 实际采购：0603 / 1uF / ±10% / 50V / X7R。 | K17: HAT-V5.epro2 / PCB2
A18: C11 | B18: 100nF / onboard MIC | C18: CC0603KRX7R9BB104 | D18: C14663 | E18: 0603 | F18: 100nF / ±10% / 50V / X7R | G18: 0603 100nF ±10% X7R;50V;100个 | H18: =HYPERLINK("https://item.taobao.com/item.htm?id=731471380840","打开订单商品") -> 打开订单商品 | I18: =HYPERLINK("https://item.szlcsc.com/15331.html","查看工程型号") -> 查看工程型号 | J18: 实际采购：0603 / 100nF / ±10% / 50V / X7R。 | K18: HAT-V5.epro2 / PCB2
A19: C12 | B19: 10uF / 1V8 | C19: C1608X5R1A106KT000E | D19: C76608 | E19: 0603 | F19: 10uF / ±10% / 10V / X5R | G19: 0603 10uF ±10% X5R;10V | H19: =HYPERLINK("https://item.taobao.com/item.htm?id=630712731066","打开订单商品") -> 打开订单商品 | I19: =HYPERLINK("https://item.szlcsc.com/77735.html","查看工程型号") -> 查看工程型号 | J19: 实际采购：0603 / 10uF / ±10% / 10V / X5R。 | K19: HAT-V5.epro2 / PCB2
A20: C13 | B20: 10uF / 3V3 | C20: C1608X5R1A106KT000E | D20: C76608 | E20: 0603 | F20: 10uF / ±10% / 10V / X5R | G20: 0603 10uF ±10% X5R;10V | H20: =HYPERLINK("https://item.taobao.com/item.htm?id=630712731066","打开订单商品") -> 打开订单商品 | I20: =HYPERLINK("https://item.szlcsc.com/77735.html","查看工程型号") -> 查看工程型号 | J20: 实际采购：0603 / 10uF / ±10% / 10V / X5R。 | K20: HAT-V5.epro2 / PCB2
A21: C14 | B21: 100nF / oscillator | C21: CC0603KRX7R9BB104 | D21: C14663 | E21: 0603 | F21: 100nF / ±10% / 50V / X7R | G21: 0603 100nF ±10% X7R;50V;100个 | H21: =HYPERLINK("https://item.taobao.com/item.htm?id=731471380840","打开订单商品") -> 打开订单商品 | I21: =HYPERLINK("https://item.szlcsc.com/15331.html","查看工程型号") -> 查看工程型号 | J21: 实际采购：0603 / 100nF / ±10% / 50V / X7R。 | K21: HAT-V5.epro2 / PCB2
A22: C15 | B22: C3216X7R1V106KT000E | C22: C3216X7R1V106KT000E | D22: C76666 | E22: 1206 | F22: 10uF / ±10% / 35V / X7R | G22: 1206 10UF ±10% X7R;35V | H22: =HYPERLINK("https://item.taobao.com/item.htm?id=730407108775","打开订单商品") -> 打开订单商品 | I22: =HYPERLINK("https://item.szlcsc.com/77793.html","查看工程型号") -> 查看工程型号 | J22: C15 使用 1206、10uF、35V、X7R 款式。 | K22: HAT-V5.epro2 / PCB2
A23: C16 | B23: 100nF / U5 | C23: CC0603KRX7R9BB104 | D23: C14663 | E23: 0603 | F23: 100nF / ±10% / 50V / X7R | G23: 0603 100nF ±10% X7R;50V;100个 | H23: =HYPERLINK("https://item.taobao.com/item.htm?id=731471380840","打开订单商品") -> 打开订单商品 | I23: =HYPERLINK("https://item.szlcsc.com/15331.html","查看工程型号") -> 查看工程型号 | J23: 实际采购：0603 / 100nF / ±10% / 50V / X7R。 | K23: HAT-V5.epro2 / PCB2
A24: C17 | B24: 100nF / U6 | C24: CC0603KRX7R9BB104 | D24: C14663 | E24: 0603 | F24: 100nF / ±10% / 50V / X7R | G24: 0603 100nF ±10% X7R;50V;100个 | H24: =HYPERLINK("https://item.taobao.com/item.htm?id=731471380840","打开订单商品") -> 打开订单商品 | I24: =HYPERLINK("https://item.szlcsc.com/15331.html","查看工程型号") -> 查看工程型号 | J24: 实际采购：0603 / 100nF / ±10% / 50V / X7R。 | K24: HAT-V5.epro2 / PCB2
A25: C18 | B25: 100nF / U7 | C25: CC0603KRX7R9BB104 | D25: C14663 | E25: 0603 | F25: 100nF / ±10% / 50V / X7R | G25: 0603 100nF ±10% X7R;50V;100个 | H25: =HYPERLINK("https://item.taobao.com/item.htm?id=731471380840","打开订单商品") -> 打开订单商品 | I25: =HYPERLINK("https://item.szlcsc.com/15331.html","查看工程型号") -> 查看工程型号 | J25: 实际采购：0603 / 100nF / ±10% / 50V / X7R。 | K25: HAT-V5.epro2 / PCB2
A26: C20 | B26: 100nF 50V / bootstrap | C26: CC0603KRX7R9BB104 | D26: C14663 | E26: 0603 | F26: 100nF / ±10% / 50V / X7R | G26: 0603 100nF ±10% X7R;50V;100个 | H26: =HYPERLINK("https://item.taobao.com/item.htm?id=731471380840","打开订单商品") -> 打开订单商品 | I26: =HYPERLINK("https://item.szlcsc.com/15331.html","查看工程型号") -> 查看工程型号 | J26: 实际采购：0603 / 100nF / ±10% / 50V / X7R。 | K26: HAT-V5.epro2 / PCB2
A27: C21 | B27: 22uF 10V X5R | C27: GRM188R61A226ME15D | D27: C84419 | E27: 0603 | F27: 22uF / ±20% / 10V / X5R | G27: 22UF 226K 10% X5R;10V;0603=100个 | H27: =HYPERLINK("https://item.taobao.com/item.htm?id=993202872551","打开订单商品") -> 打开订单商品 | I27: =HYPERLINK("https://item.szlcsc.com/85589.html","查看工程型号") -> 查看工程型号 | J27: 实际采购：0603 / 22uF / ±10% / 10V / X5R。 | K27: HAT-V5.epro2 / PCB2
A28: C22 | B28: 22uF 10V X5R | C28: GRM188R61A226ME15D | D28: C84419 | E28: 0603 | F28: 22uF / ±20% / 10V / X5R | G28: 22UF 226K 10% X5R;10V;0603=100个 | H28: =HYPERLINK("https://item.taobao.com/item.htm?id=993202872551","打开订单商品") -> 打开订单商品 | I28: =HYPERLINK("https://item.szlcsc.com/85589.html","查看工程型号") -> 查看工程型号 | J28: 实际采购：0603 / 22uF / ±10% / 10V / X5R。 | K28: HAT-V5.epro2 / PCB2
A29: C26 | B29: 100nF / 1V8 | C29: CC0603KRX7R9BB104 | D29: C14663 | E29: 0603 | F29: 100nF / ±10% / 50V / X7R | G29: 0603 100nF ±10% X7R;50V;100个 | H29: =HYPERLINK("https://item.taobao.com/item.htm?id=731471380840","打开订单商品") -> 打开订单商品 | I29: =HYPERLINK("https://item.szlcsc.com/15331.html","查看工程型号") -> 查看工程型号 | J29: 实际采购：0603 / 100nF / ±10% / 50V / X7R。 | K29: HAT-V5.epro2 / PCB2
A30: C27 | B30: 1uF | C30: CC0603KRX5R9BB105 | D30: C128624 | E30: 0603 | F30: 1uF / ±10% / 50V / X5R | G30: 0603 1uF ±10% X7R;50V | H30: =HYPERLINK("https://item.taobao.com/item.htm?id=630712731066","打开订单商品") -> 打开订单商品 | I30: =HYPERLINK("https://www.lcsc.com/product-detail/C128624.html","查看工程型号") -> 查看工程型号 | J30: 实际采购：0603 / 1uF / ±10% / 50V / X7R。 | K30: HAT-V5.epro2 / PCB2
A31: C28 | B31: 100nF | C31: CC0603KRX7R9BB104 | D31: C14663 | E31: 0603 | F31: 100nF / ±10% / 50V / X7R | G31: 0603 100nF ±10% X7R;50V;100个 | H31: =HYPERLINK("https://item.taobao.com/item.htm?id=731471380840","打开订单商品") -> 打开订单商品 | I31: =HYPERLINK("https://item.szlcsc.com/15331.html","查看工程型号") -> 查看工程型号 | J31: 实际采购：0603 / 100nF / ±10% / 50V / X7R。 | K31: HAT-V5.epro2 / PCB2
A32: C29 | B32: 1uF | C32: CC0603KRX5R9BB105 | D32: C128624 | E32: 0603 | F32: 1uF / ±10% / 50V / X5R | G32: 0603 1uF ±10% X7R;50V | H32: =HYPERLINK("https://item.taobao.com/item.htm?id=630712731066","打开订单商品") -> 打开订单商品 | I32: =HYPERLINK("https://www.lcsc.com/product-detail/C128624.html","查看工程型号") -> 查看工程型号 | J32: 实际采购：0603 / 1uF / ±10% / 50V / X7R。 | K32: HAT-V5.epro2 / PCB2
A33: C30 | B33: 100nF | C33: CC0603KRX7R9BB104 | D33: C14663 | E33: 0603 | F33: 100nF / ±10% / 50V / X7R | G33: 0603 100nF ±10% X7R;50V;100个 | H33: =HYPERLINK("https://item.taobao.com/item.htm?id=731471380840","打开订单商品") -> 打开订单商品 | I33: =HYPERLINK("https://item.szlcsc.com/15331.html","查看工程型号") -> 查看工程型号 | J33: 实际采购：0603 / 100nF / ±10% / 50V / X7R。 | K33: HAT-V5.epro2 / PCB2
A34: C31 | B34: 1uF | C34: CC0603KRX5R9BB105 | D34: C128624 | E34: 0603 | F34: 1uF / ±10% / 50V / X5R | G34: 0603 1uF ±10% X7R;50V | H34: =HYPERLINK("https://item.taobao.com/item.htm?id=630712731066","打开订单商品") -> 打开订单商品 | I34: =HYPERLINK("https://www.lcsc.com/product-detail/C128624.html","查看工程型号") -> 查看工程型号 | J34: 实际采购：0603 / 1uF / ±10% / 50V / X7R。 | K34: HAT-V5.epro2 / PCB2
A35: C32 | B35: 100nF | C35: CC0603KRX7R9BB104 | D35: C14663 | E35: 0603 | F35: 100nF / ±10% / 50V / X7R | G35: 0603 100nF ±10% X7R;50V;100个 | H35: =HYPERLINK("https://item.taobao.com/item.htm?id=731471380840","打开订单商品") -> 打开订单商品 | I35: =HYPERLINK("https://item.szlcsc.com/15331.html","查看工程型号") -> 查看工程型号 | J35: 实际采购：0603 / 100nF / ±10% / 50V / X7R。 | K35: HAT-V5.epro2 / PCB2
A36: C33 | B36: 1uF | C36: CC0603KRX5R9BB105 | D36: C128624 | E36: 0603 | F36: 1uF / ±10% / 50V / X5R | G36: 0603 1uF ±10% X7R;50V | H36: =HYPERLINK("https://item.taobao.com/item.htm?id=630712731066","打开订单商品") -> 打开订单商品 | I36: =HYPERLINK("https://www.lcsc.com/product-detail/C128624.html","查看工程型号") -> 查看工程型号 | J36: 实际采购：0603 / 1uF / ±10% / 50V / X7R。 | K36: HAT-V5.epro2 / PCB2
A37: C34 | B37: 10nF | C37: CC0603KRX7R9BB103 | D37: C100042 | E37: 0603 | F37: 10nF / ±10% / 50V / X7R | G37: 0603 10NF 50V 10% 100个 | H37: =HYPERLINK("https://item.taobao.com/item.htm?id=610558214623","打开订单商品") -> 打开订单商品 | I37: =HYPERLINK("https://item.szlcsc.com/101256.html","查看工程型号") -> 查看工程型号 | J37: 实际采购：0603 / 10nF / ±10% / 50V / X7R。 | K37: HAT-V5.epro2 / PCB2
A38: C35 | B38: 1uF | C38: CC0603KRX5R9BB105 | D38: C128624 | E38: 0603 | F38: 1uF / ±10% / 50V / X5R | G38: 0603 1uF ±10% X7R;50V | H38: =HYPERLINK("https://item.taobao.com/item.htm?id=630712731066","打开订单商品") -> 打开订单商品 | I38: =HYPERLINK("https://www.lcsc.com/product-detail/C128624.html","查看工程型号") -> 查看工程型号 | J38: 实际采购：0603 / 1uF / ±10% / 50V / X7R。 | K38: HAT-V5.epro2 / PCB2
A39: C36 | B39: 100nF | C39: CC0603KRX7R9BB104 | D39: C14663 | E39: 0603 | F39: 100nF / ±10% / 50V / X7R | G39: 0603 100nF ±10% X7R;50V;100个 | H39: =HYPERLINK("https://item.taobao.com/item.htm?id=731471380840","打开订单商品") -> 打开订单商品 | I39: =HYPERLINK("https://item.szlcsc.com/15331.html","查看工程型号") -> 查看工程型号 | J39: 实际采购：0603 / 100nF / ±10% / 50V / X7R。 | K39: HAT-V5.epro2 / PCB2
A40: C37 | B40: 10uF / 3V3 | C40: C1608X5R1A106KT000E | D40: C76608 | E40: 0603 | F40: 10uF / ±10% / 10V / X5R | G40: 0603 10uF ±10% X5R;10V | H40: =HYPERLINK("https://item.taobao.com/item.htm?id=630712731066","打开订单商品") -> 打开订单商品 | I40: =HYPERLINK("https://item.szlcsc.com/77735.html","查看工程型号") -> 查看工程型号 | J40: 实际采购：0603 / 10uF / ±10% / 10V / X5R。 | K40: HAT-V5.epro2 / PCB2
A41: C38 | B41: 100nF / codec reset | C41: CC0603KRX7R9BB104 | D41: C14663 | E41: 0603 | F41: 100nF / ±10% / 50V / X7R | G41: 0603 100nF ±10% X7R;50V;100个 | H41: =HYPERLINK("https://item.taobao.com/item.htm?id=731471380840","打开订单商品") -> 打开订单商品 | I41: =HYPERLINK("https://item.szlcsc.com/15331.html","查看工程型号") -> 查看工程型号 | J41: 实际采购：0603 / 100nF / ±10% / 50V / X7R。 | K41: HAT-V5.epro2 / PCB2
...

Sheet IMU位号BOM
A2: IMU 位号 BOM
A3: 源：IMU-TO-DLX-V2.epro2 / PCB1；25 个器件，工程原始属性保留。
A4: 实际采购款式见 G 列，原工程型号与参数保留备查。
A5: D2 实际采购为0603蓝色LED，原工程器件记录保留。
A6: 器件用量按实际位号统计，采购商品已在作者实机验证可用。
A7: 位号 | B7: 用途 / 位号原文 | C7: 工程完整型号 | D7: 工程立创料号 | E7: 工程封装 | F7: 工程关键参数 | G7: 当前采购规格 / 订单款式 | H7: 订单商品链接 | I7: 工程BOM型号链接 | J7: 用料说明 | K7: 工程来源
A8: C1 | B8: 4.7uF 25V | C8: CL21A475KAQNNNE | D8: C1779 | E8: 0805 | F8: 4.7uF / ±10% / 25V / X5R | G8: 0805 4.7UF ±10% X7R;25V | H8: =HYPERLINK("https://item.taobao.com/item.htm?id=977236759812","打开订单商品") -> 打开订单商品 | I8: =HYPERLINK("https://www.lcsc.com/product-detail/C1779.html","查看工程型号") -> 查看工程型号 | J8: 实际采购：0805 / 4.7uF / ±10% / 25V / X7R。 | K8: IMU-TO-DLX-V2.epro2 / PCB1
A9: C2 | B9: 100nF 50V | C9: CL10B104JB8NNNC | D9: C24452 | E9: 0603 | F9: 100nF / ±5% / 50V / X7R | G9: 0603 100nF ±10% X7R;50V;100个 | H9: =HYPERLINK("https://item.taobao.com/item.htm?id=731471380840","打开订单商品") -> 打开订单商品 | I9: =HYPERLINK("https://item.szlcsc.com/25192.html","查看工程型号") -> 查看工程型号 | J9: 实际采购：0603 / 100nF / ±10% / 50V / X7R。 | K9: IMU-TO-DLX-V2.epro2 / PCB1
A10: C3 | B10: 4.7uF 25V | C10: CL21A475KAQNNNE | D10: C1779 | E10: 0805 | F10: 4.7uF / ±10% / 25V / X5R | G10: 0805 4.7UF ±10% X7R;25V | H10: =HYPERLINK("https://item.taobao.com/item.htm?id=977236759812","打开订单商品") -> 打开订单商品 | I10: =HYPERLINK("https://www.lcsc.com/product-detail/C1779.html","查看工程型号") -> 查看工程型号 | J10: 实际采购：0805 / 4.7uF / ±10% / 25V / X7R。 | K10: IMU-TO-DLX-V2.epro2 / PCB1
A11: C4 | B11: 100nF 50V | C11: CL10B104JB8NNNC | D11: C24452 | E11: 0603 | F11: 100nF / ±5% / 50V / X7R | G11: 0603 100nF ±10% X7R;50V;100个 | H11: =HYPERLINK("https://item.taobao.com/item.htm?id=731471380840","打开订单商品") -> 打开订单商品 | I11: =HYPERLINK("https://item.szlcsc.com/25192.html","查看工程型号") -> 查看工程型号 | J11: 实际采购：0603 / 100nF / ±10% / 50V / X7R。 | K11: IMU-TO-DLX-V2.epro2 / PCB1
A12: C5 | B12: 100nF / MCU | C12: CL10B104JB8NNNC | D12: C24452 | E12: 0603 | F12: 100nF / ±5% / 50V / X7R | G12: 0603 100nF ±10% X7R;50V;100个 | H12: =HYPERLINK("https://item.taobao.com/item.htm?id=731471380840","打开订单商品") -> 打开订单商品 | I12: =HYPERLINK("https://item.szlcsc.com/25192.html","查看工程型号") -> 查看工程型号 | J12: 实际采购：0603 / 100nF / ±10% / 50V / X7R。 | K12: IMU-TO-DLX-V2.epro2 / PCB1
A13: C6 | B13: 1uF / MCU | C13: CL10A105KB8NNNC | D13: C15849 | E13: 0603 | F13: 1uF / ±10% / 50V / X5R | G13: 0603 1uF ±10% X7R;50V | H13: =HYPERLINK("https://item.taobao.com/item.htm?id=630712731066","打开订单商品") -> 打开订单商品 | I13: =HYPERLINK("https://item.szlcsc.com/16531.html","查看工程型号") -> 查看工程型号 | J13: 实际采购：0603 / 1uF / ±10% / 50V / X7R。 | K13: IMU-TO-DLX-V2.epro2 / PCB1
A14: C7 | B14: 100nF / VDD_IO | C14: CL10B104JB8NNNC | D14: C24452 | E14: 0603 | F14: 100nF / ±5% / 50V / X7R | G14: 0603 100nF ±10% X7R;50V;100个 | H14: =HYPERLINK("https://item.taobao.com/item.htm?id=731471380840","打开订单商品") -> 打开订单商品 | I14: =HYPERLINK("https://item.szlcsc.com/25192.html","查看工程型号") -> 查看工程型号 | J14: 实际采购：0603 / 100nF / ±10% / 50V / X7R。 | K14: IMU-TO-DLX-V2.epro2 / PCB1
A15: C8 | B15: 100nF / VDD | C15: CL10B104JB8NNNC | D15: C24452 | E15: 0603 | F15: 100nF / ±5% / 50V / X7R | G15: 0603 100nF ±10% X7R;50V;100个 | H15: =HYPERLINK("https://item.taobao.com/item.htm?id=731471380840","打开订单商品") -> 打开订单商品 | I15: =HYPERLINK("https://item.szlcsc.com/25192.html","查看工程型号") -> 查看工程型号 | J15: 实际采购：0603 / 100nF / ±10% / 50V / X7R。 | K15: IMU-TO-DLX-V2.epro2 / PCB1
A16: C9 | B16: 1uF / IMU local | C16: CL10A105KB8NNNC | D16: C15849 | E16: 0603 | F16: 1uF / ±10% / 50V / X5R | G16: 0603 1uF ±10% X7R;50V | H16: =HYPERLINK("https://item.taobao.com/item.htm?id=630712731066","打开订单商品") -> 打开订单商品 | I16: =HYPERLINK("https://item.szlcsc.com/16531.html","查看工程型号") -> 查看工程型号 | J16: 实际采购：0603 / 1uF / ±10% / 50V / X7R。 | K16: IMU-TO-DLX-V2.epro2 / PCB1
A17: C10 | B17: 100nF / buffer | C17: CL10B104JB8NNNC | D17: C24452 | E17: 0603 | F17: 100nF / ±5% / 50V / X7R | G17: 0603 100nF ±10% X7R;50V;100个 | H17: =HYPERLINK("https://item.taobao.com/item.htm?id=731471380840","打开订单商品") -> 打开订单商品 | I17: =HYPERLINK("https://item.szlcsc.com/25192.html","查看工程型号") -> 查看工程型号 | J17: 实际采购：0603 / 100nF / ±10% / 50V / X7R。 | K17: IMU-TO-DLX-V2.epro2 / PCB1
A18: D1 | B18: PESD5V0S1BA / 5V bidirectional | C18: PESD5V0S1BA | D18: C330094 | E18: SOD-323 | F18: 反向截止电压(Vrwm):5V@Max；最大钳位电压:10V；峰值脉冲电流(Ipp)@10/1000us:5A@8/20us；击穿电压:5.8V | G18: 商品无选项，按商品标题完整型号购买 | H18: =HYPERLINK("https://item.taobao.com/item.htm?id=891785167202","打开订单商品") -> 打开订单商品 | I18: =HYPERLINK("https://www.lcsc.com/product-detail/C330094.html","查看工程型号") -> 查看工程型号 | J18: PESD5V0S1BA / SOD-323 双向TVS，按商品完整型号购买。 | K18: IMU-TO-DLX-V2.epro2 / PCB1
A19: D2 | B19: DEBUG LED | C19: 19-217/GHC-YR1S2/3T | D19: C72043 | E19: 0603 | F19: 110mW | G19: 0603 蓝色=100个 | H19: =HYPERLINK("https://item.taobao.com/item.htm?id=1025817117811","打开订单商品") -> 打开订单商品 | I19: =HYPERLINK("https://www.lcsc.com/product-detail/Light-Emitting-Diodes-LED_Everlight-Elec-19-217-GHC-YR1S2-3T_C72043.html","查看工程型号") -> 查看工程型号 | J19: 实际采购：0603 蓝色LED，100个包装。 | K19: IMU-TO-DLX-V2.epro2 / PCB1
A20: J1 | B20: DXL BUS / JST EH 3P | C20: B3B-EH-A(LF)(SN) | D20: C160259 | E20: 插件,P=2.5mm | F20: 250V / 3A | G20: EH2.5MM 3P直针座（50个） | H20: =HYPERLINK("https://item.taobao.com/item.htm?id=832569969546","打开订单商品") -> 打开订单商品 | I20: =HYPERLINK("https://item.szlcsc.com/171639.html","查看工程型号") -> 查看工程型号 | J20: EH 3P 直针座，HAT 两只、IMU 一只。 | K20: IMU-TO-DLX-V2.epro2 / PCB1
A21: J2 | B21: SWD 1x5 | C21: PZ254V-11-05P | D21: C492404 | E21: 插件,P=2.54mm | F21: 3A | G21: 1*5P直针 铜（30条） | H21: =HYPERLINK("https://item.taobao.com/item.htm?id=606816197525","打开订单商品") -> 打开订单商品 | I21: =HYPERLINK("https://item.szlcsc.com/502960.html","查看工程型号") -> 查看工程型号 | J21: 1×5P / 2.54mm 直排针，用于SWD烧录口。 | K21: IMU-TO-DLX-V2.epro2 / PCB1
A22: R1 | B22: 0R / DXL_VDD link | C22: 0603WAF0000T5E | D22: C21189 | E22: 0603 | F22: 0Ω / ±1% / - / 100mW | G22: 0R/0欧;0603 1%（100个） | H22: =HYPERLINK("https://item.taobao.com/item.htm?id=947267344247","打开订单商品") -> 打开订单商品 | I22: =HYPERLINK("https://item.szlcsc.com/21903.html","查看工程型号") -> 查看工程型号 | J22: 0Ω / 0603；HAT R33 按后续 0Ω / C21189 补丁计入。 | K22: IMU-TO-DLX-V2.epro2 / PCB1
A23: R2 | B23: 10k / NRST pull-up | C23: RC0603FR-0710KL | D23: C98220 | E23: 0603 | F23: 10kΩ / ±1% / ±100ppm/℃ / 100mW | G23: 10K;0603 1%（100个） | H23: =HYPERLINK("https://item.taobao.com/item.htm?id=947267344247","打开订单商品") -> 打开订单商品 | I23: =HYPERLINK("https://item.szlcsc.com/99429.html","查看工程型号") -> 查看工程型号 | J23: 10kΩ / ±1% / 0603；HAT 十二只、IMU 三只。 | K23: IMU-TO-DLX-V2.epro2 / PCB1
A24: R3 | B24: 100k / BOOT0 pull-down | C24: RC0603FR-07100KL | D24: C14675 | E24: 0603 | F24: 100kΩ / ±1% / ±100ppm/℃ / 100mW | G24: 100K;0603 1%（100个） | H24: =HYPERLINK("https://item.taobao.com/item.htm?id=947267344247","打开订单商品") -> 打开订单商品 | I24: =HYPERLINK("https://item.szlcsc.com/15343.html","查看工程型号") -> 查看工程型号 | J24: 100kΩ / ±1% / 0603。 | K24: IMU-TO-DLX-V2.epro2 / PCB1
A25: R4 | B25: 10k / IMU CS pull-up | C25: RC0603FR-0710KL | D25: C98220 | E25: 0603 | F25: 10kΩ / ±1% / ±100ppm/℃ / 100mW | G25: 10K;0603 1%（100个） | H25: =HYPERLINK("https://item.taobao.com/item.htm?id=947267344247","打开订单商品") -> 打开订单商品 | I25: =HYPERLINK("https://item.szlcsc.com/99429.html","查看工程型号") -> 查看工程型号 | J25: 10kΩ / ±1% / 0603；HAT 十二只、IMU 三只。 | K25: IMU-TO-DLX-V2.epro2 / PCB1
A26: R5 | B26: 10k / TX disable pull-up | C26: RC0603FR-0710KL | D26: C98220 | E26: 0603 | F26: 10kΩ / ±1% / ±100ppm/℃ / 100mW | G26: 10K;0603 1%（100个） | H26: =HYPERLINK("https://item.taobao.com/item.htm?id=947267344247","打开订单商品") -> 打开订单商品 | I26: =HYPERLINK("https://item.szlcsc.com/99429.html","查看工程型号") -> 查看工程型号 | J26: 10kΩ / ±1% / 0603；HAT 十二只、IMU 三只。 | K26: IMU-TO-DLX-V2.epro2 / PCB1
A27: R6 | B27: 33R / DXL TX series | C27: 0603WAF330JT5E | D27: C23140 | E27: 0603 | F27: 33Ω / ±1% / ±100ppm/℃ / 100mW | G27: 33R/33欧;0603 1%（100个） | H27: =HYPERLINK("https://item.taobao.com/item.htm?id=947267344247","打开订单商品") -> 打开订单商品 | I27: =HYPERLINK("https://item.szlcsc.com/23867.html","查看工程型号") -> 查看工程型号 | J27: 33Ω / ±1% / 0603，用于IMU R6。 | K27: IMU-TO-DLX-V2.epro2 / PCB1
A28: R7 | B28: 1k / debug LED | C28: 0603WAF1001T5E | D28: C21190 | E28: 0603 | F28: 1kΩ / ±1% / ±100ppm/℃ / 100mW | G28: 1K;0603 1%（100个） | H28: =HYPERLINK("https://item.taobao.com/item.htm?id=947267344247","打开订单商品") -> 打开订单商品 | I28: =HYPERLINK("https://item.szlcsc.com/21904.html","查看工程型号") -> 查看工程型号 | J28: 1kΩ / ±1% / 0603，八月备料订单。 | K28: IMU-TO-DLX-V2.epro2 / PCB1
A29: U1 | B29: STM32G031F8P6 | C29: STM32G031F8P6 | D29: C529334 | E29: TSSOP-20 | F29: CPU内核:ARM Cortex-M0+；CPU最大主频:64MHz；CPU位数:32 Bit | G29: 全新原装 | H29: =HYPERLINK("https://item.taobao.com/item.htm?id=726808419708","打开订单商品") -> 打开订单商品 | I29: =HYPERLINK("https://item.szlcsc.com/549612.html","查看工程型号") -> 查看工程型号 | J29: STM32G031F8P6 / TSSOP-20，按商品完整型号购买。 | K29: IMU-TO-DLX-V2.epro2 / PCB1
A30: U2 | B30: LSM6DSV16XTR | C30: LSM6DSV16XTR | D30: C5267406 | E30: LGA-14(2.5x3) | F30: 传感器类型:IMU(加速度计+陀螺仪)；接口类型:I2C；SPI | G30: LSM6DSV16XTR | H30: =HYPERLINK("https://item.taobao.com/item.htm?id=640391703111","打开订单商品") -> 打开订单商品 | I30: =HYPERLINK("https://item.szlcsc.com/5993815.html","查看工程型号") -> 查看工程型号 | J30: LSM6DSV16XTR / LGA-14，在多型号商品页选择 LSM6DSV16XTR。 | K30: IMU-TO-DLX-V2.epro2 / PCB1
A31: U3 | B31: TLV70433DBVR | C31: TLV70433DBVR | D31: C94917 | E31: SOT-23-5 | F31: 输出极性:正极；工作电压:24V；输出电压:3.3V；输出电流:150mA；电源纹波抑制比(PSRR):60dB@(100kHz)；输出类型:固定 | G31: TLV70433DBVR | H31: =HYPERLINK("https://item.taobao.com/item.htm?id=747094785928","打开订单商品") -> 打开订单商品 | I31: =HYPERLINK("https://www.lcsc.com/product-detail/C94917.html","查看工程型号") -> 查看工程型号 | J31: TLV70433DBVR / 3.3V / SOT-23-5。 | K31: IMU-TO-DLX-V2.epro2 / PCB1
A32: U4 | B32: SN74LVC2G125DCUR | C32: SN74LVC2G125DCUR | D32: C21404 | E32: VSSOP-8 | F32: 输入类型:-；工作电压:1.65V~5.5V；元件数:2；每个元件位数:1；灌电流(IOL):32mA；拉电流(IOH):32mA | G32: 商品无选项，按商品标题完整型号购买 | H32: =HYPERLINK("https://item.taobao.com/item.htm?id=705642638300","打开订单商品") -> 打开订单商品 | I32: =HYPERLINK("https://www.lcsc.com/product-detail/C21404.html","查看工程型号") -> 查看工程型号 | J32: SN74LVC2G125DCUR / VSSOP-8，按商品完整型号购买。 | K32: IMU-TO-DLX-V2.epro2 / PCB1

Sheet 配件与耗材
A2: 鸭子本体用料
A3: 鸭子本体配套材料：HAT/IMU接口使用EH，飞特舵机使用AMP2.0成品线（10cm、20cm）。PCB原器件表不动，工具见独立工作表。
A4: 舵机为HD-1910-C001，整机15只；电池按NP-F550的2电＋标准双充套装选购。
A5: 订单商品金额按一拍记录；包装或购入数量包含备料。金额依据订单数据.xlsx。
A6: 类别 | B6: 商品 / 用品 | C6: 具体规格 | D6: 用量或购买条件 | E6: 订单店铺 | F6: 商品链接 | G6: 订单原款式 | H6: 每拍含量 | I6: 购买说明 | J6: 订单源行 | K6: 订单商品金额 / 拍(元)
A7: 定制PCB | B7: HAT 裸板 | C7: HAT-V5，65×30.9mm，两层板；按对应工程生成生产资料 | D7: 有券免费；无券20元5张（4元/张） | E7: PCB打样平台 | F7: =HYPERLINK("https://www.jlc.com/","PCB打样入口") -> PCB打样入口 | G7: 定制打样入口，不是现成商品 | I7: 裸板需定制；R33按0Ω采购，TH1可用原村田PRG18BB101MB1RB；使用本项目对应工程。 | J7: 未在淘宝订单中记录
A8: 定制PCB | B8: IMU 裸板 | C8: IMU-TO-DLX-V2；按对应工程生成生产资料 | D8: 有券免费；无券20元5张（4元/张） | E8: PCB打样平台 | F8: =HYPERLINK("https://www.jlc.com/","PCB打样入口") -> PCB打样入口 | G8: 定制打样入口，不是现成商品 | I8: 使用对应 IMU 工程，裸板不是可直接购买的标准模块。 | J8: 未在淘宝订单中记录
A9: 配套接插件 | B9: EH 2P 母壳 | C9: EH 2P，配 HAT J1/J2/J9 | D9: 按实际接线；最多3只/板 | E9: 启色数码旗舰店 | F9: =HYPERLINK("https://item.taobao.com/item.htm?id=832569969546","打开订单商品") -> 打开订单商品 | G9: EH2.5MM 2P胶壳（50个） | H9: 50 | I9: 每只母壳配2个EH压接端子；按EH2.5款式购买，与板上的EH接口配套。 | J9: 82 | K9: 2.2
A10: 配套接插件 | B10: EH 3P 母壳 | C10: EH 3P，配 HAT J13/J14、IMU J1 | D10: 按实际接线；最多3只/套 | E10: 启色数码旗舰店 | F10: =HYPERLINK("https://item.taobao.com/item.htm?id=832569969546","打开订单商品") -> 打开订单商品 | G10: EH2.5MM 3P胶壳（50个） | H10: 50 | I10: 每只母壳还需3个压接端子。 | J10: 81 | K10: 2.8
A11: 配套接插件 | B11: EH 压接端子 | C11: EH2.5MM 端子 | D11: 每个使用的插孔1个 | E11: 启色数码旗舰店 | F11: =HYPERLINK("https://item.taobao.com/item.htm?id=832569969546","打开订单商品") -> 打开订单商品 | G11: EH2.5MM 端子（100个） | H11: 100 | I11: 与EH母壳成套使用，按EH2.5MM端子款式购买。 | J11: 83 | K11: 3.5
A12: 信号线 | B12: SH1.0 4P 转杜邦母线 | C12: SH1.0 4P / 20cm / 杜邦母 | D12: 按连接方案选用 | E12: 信容芯旗舰店 | F12: =HYPERLINK("https://item.taobao.com/item.htm?id=895049863252","打开订单商品") -> 打开订单商品 | G12: 0.2m;1.0-4P转杜邦母（5条） | H12: 5 | I12: 用于外部接口转接；每根线的脚序按 HAT J5 与模块核对，不按线色猜。 | J12: 77 | K12: 4.56
A13: 外接模块 | B13: 扬声器 | C13: 3525 腔体 / 4Ω 3W | D13: 按音频方案选用 | E13: 深圳市优信电子科技有限公司 | F13: =HYPERLINK("https://item.taobao.com/item.htm?id=683920556900","打开订单商品") -> 打开订单商品 | G13: 3525腔体-4Ω3W/喇叭 | H13: 1 | I13: 订单自带1.25端子；HAT板座是 EH 2P，需改接或转接，不能直接认为插头相同。 | J13: 103 | K13: 3.08
A14: 外接模块 | B14: 8×8 ToF 测距模块 | C14: VL53L5X V2模块配盖片（商品标题 VL53L5CX） | D14: 按功能需求选用 | E14: 都会明武电子 | F14: =HYPERLINK("https://item.taobao.com/item.htm?id=737603917521","打开订单商品") -> 打开订单商品 | G14: VL53L5X V2模块配盖片 | H14: 1 | I14: 外接模块，不是 PCB 上的裸芯片；模块接线和供电按已验证方案。 | J14: 92 | K14: 49.5
A15: 外接主控 | B15: Radxa ZERO 3W | C15: 2GB RAM / 无eMMC / 带排针 | D15: 1块/HAT（如未已有） | E15: 瑞莎计算机(深圳)有限公司 | F15: =HYPERLINK("https://item.taobao.com/item.htm?id=763812025816","打开订单商品") -> 打开订单商品 | G15: 2GB RAM 无 eMMC 带排针[【Microduck 原版主板】] | H15: 1 | I15: 已完成订单的主板款式；属于配套主控，不计入 HAT 84 个器件。 | J15: 100 | K15: 309
A16: 舵机 | B16: 飞特 HD1910 串口总线舵机 | C16: HD-1910-C001 | D16: 15只/整机 | E16: 深圳飞特舵机工厂店 | F16: =HYPERLINK("https://item.taobao.com/item.htm?id=1078248851201","打开订单商品") -> 打开订单商品 | G16: HD-1910-C001 | H16: 1 | I16: 作者两次订单分别购入13只和2只，共15只；选择 HD-1910-C001 款式。 | J16: 104 | K16: 99
A17: 摄像头 | B17: Radxa 8M 219 摄像头 | C17: IMX219 / 800万像素 / 瑞莎8M 219 | D17: 按摄像头方案选用 | E17: 瑞莎计算机(深圳)有限公司 | F17: =HYPERLINK("https://item.taobao.com/item.htm?id=768918125679","打开订单商品") -> 打开订单商品 | G17: 8M 219 摄像头[【适配3W/3E/3A/3C/CM5/4系列】] | H17: 1 | I17: 按原订单的8M 219摄像头款式购买。 | J17: 180 | K17: 129.99
A18: 电池 | B18: NP-F550 电池与双充套装 | C18: 沣标 NP-F550 / 2200mAh / 2块电池＋标准双充 | D18: 1套含2电＋双充；按NP-F供电安装方案使用 | E18: fb数码旗舰店 | F18: =HYPERLINK("https://item.taobao.com/item.htm?id=585415365001","打开订单商品") -> 打开订单商品 | G18: 【NP-F550补光灯专用▲2200mAh】2电+标准双充套裝 | H18: 1 | I18: 按“NP-F550补光灯专用▲2200mAh，2电+标准双充套裝”原款式购买。 | J18: 22 | K18: 84.59
A19: AMP线材 | B19: AMP2.0 3P 舵机线 20cm | C19: 200mm / 1007 / 24AWG / 3P / AMP2.0 | D19: 按布线长度选择；原订单30条 | E19: 永茂电子 | F19: =HYPERLINK("https://item.taobao.com/item.htm?id=825340808235","打开订单商品") -> 打开订单商品 | G19: 200mm;1007/24#;3P;AMP2.0 | H19: 1 | I19: 用于飞特舵机线束；10cm和20cm按实际走线位置选择。 | J19: 6 | K19: 0.9
A20: AMP线材 | B20: AMP2.0 3P 舵机线 10cm | C20: 100mm / 1007 / 24AWG / 3P / AMP2.0 | D20: 按布线长度选择；原订单30条 | E20: 永茂电子 | F20: =HYPERLINK("https://item.taobao.com/item.htm?id=825340808235","打开订单商品") -> 打开订单商品 | G20: 100mm;1007/24#;3P;AMP2.0 | H20: 1 | I20: 与20cm线是不同长度选项，数量按实际线束方案准备。 | J20: 36 | K20: 0.9
A21: 线材 | B21: 22AWG 三芯硅胶排线 | C21: 黑色 / 3芯 / 22AWG / 1m | D21: 自制线束按长度裁剪 | E21: 萨牛旗舰店 | F21: =HYPERLINK("https://item.taobao.com/item.htm?id=781764816472","打开订单商品") -> 打开订单商品 | G21: 黑色;3芯;22AWG;1m | H21: 1 | I21: 订单共购入3米；此行选用2米订单的商品链接与原款式。 | J21: 29 | K21: 3.63
A22: 线材 | B22: 22AWG 单芯硅胶线 | C22: 黑色 / 22AWG / 0.33mm² / 2m | D22: 按接线需求裁剪 | E22: 渡竹旗舰店 | F22: =HYPERLINK("https://item.taobao.com/item.htm?id=736162720327","打开订单商品") -> 打开订单商品 | G22: 22AWG(0.33平方)黑色 2米 | H22: 1 | I22: 用于自制接线，按22AWG黑色2米款式购买。 | J22: 32 | K22: 3.42
A23: 线束绝缘 | B23: 彩色热缩管套装 | C23: 164片 / 彩色 / 2倍收缩 | D23: 按线束制作需要选用 | E23: 圣佰路旗舰店 | F23: =HYPERLINK("https://item.taobao.com/item.htm?id=945215173380","打开订单商品") -> 打开订单商品 | G23: 袋装 164片 彩色 【2倍收缩】 | H23: 1 | I23: 用于接线处绝缘及整理。 | J23: 37 | K23: 0.99
A24: 轴承 | B24: 6700 开式薄壁轴承 | C24: 6700开式 / 10×15×3mm / 轴承钢精品级 | D24: 按打印模型轴承位；订单共购入5只（含备料） | E24: 优可吉轴承销售店 | F24: =HYPERLINK("https://item.taobao.com/item.htm?id=625390659071","打开订单商品") -> 打开订单商品 | G24: 6700开式【轴承钢·精品级】10*15*3MM | H24: 1 | I24: 尺寸顺序为内径×外径×宽度；两次订单为3只和2只。 | J24: 111 | K24: 1.94
A25: 轴承 | B25: ET2216 薄壁轴承 | C25: ET2216 / 16×22×4mm / 轴承钢精品级 | D25: 按打印模型轴承位；订单共购入12只（含备料） | E25: 优可吉轴承销售店 | F25: =HYPERLINK("https://item.taobao.com/item.htm?id=733598659967","打开订单商品") -> 打开订单商品 | G25: ET2216【精品级】16*22*4MM[轴承钢] | H25: 1 | I25: 尺寸顺序为内径×外径×宽度；两次订单为10只和2只。 | J25: 112 | K25: 2.91
A26: 螺丝 | B26: M2×4 十字盘头平尾自攻螺丝 | C26: 铁镀镍 / 十字圆头 / 平尾自攻 / M2×4 | D26: 按模型对应孔位选用 | E26: 固万基官方旗舰店 | F26: =HYPERLINK("https://item.taobao.com/item.htm?id=534923831046","打开订单商品") -> 打开订单商品 | G26: M2*4[200只]镀镍 | H26: 200 | I26: 按打印模型及对应安装位置选择长度；每包数量是备料数量。 | J26: 88 | K26: 3.03
A27: 螺丝 | B27: M2×5 十字盘头平尾自攻螺丝 | C27: 铁镀镍 / 十字圆头 / 平尾自攻 / M2×5 | D27: 按模型对应孔位选用 | E27: 固万基官方旗舰店 | F27: =HYPERLINK("https://item.taobao.com/item.htm?id=534923831046","打开订单商品") -> 打开订单商品 | G27: M2*5[200只]镀镍 | H27: 200 | I27: 按打印模型及对应安装位置选择长度；每包数量是备料数量。原订单商品金额为0元（订单优惠），不代表常规售价。 | J27: 12 | K27: 0
A28: 螺丝 | B28: M2×6 十字盘头平尾自攻螺丝 | C28: 铁镀镍 / 十字圆头 / 平尾自攻 / M2×6 | D28: 按模型对应孔位选用 | E28: 固万基官方旗舰店 | F28: =HYPERLINK("https://item.taobao.com/item.htm?id=534923831046","打开订单商品") -> 打开订单商品 | G28: M2*6[200只]镀镍 | H28: 200 | I28: 按打印模型及对应安装位置选择长度；每包数量是备料数量。 | J28: 87 | K28: 3.31
A29: 螺丝 | B29: M2×8 十字盘头平尾自攻螺丝 | C29: 铁镀镍 / 十字圆头 / 平尾自攻 / M2×8 | D29: 按模型对应孔位选用 | E29: 固万基官方旗舰店 | F29: =HYPERLINK("https://item.taobao.com/item.htm?id=534923831046","打开订单商品") -> 打开订单商品 | G29: M2*8[200只]镀镍 | H29: 200 | I29: 按打印模型及对应安装位置选择长度；每包数量是备料数量。 | J29: 86 | K29: 3.59
A30: 螺丝 | B30: M2×12 十字盘头平尾自攻螺丝 | C30: 铁镀镍 / 十字圆头 / 平尾自攻 / M2×12 | D30: 按模型对应孔位选用 | E30: 固万基官方旗舰店 | F30: =HYPERLINK("https://item.taobao.com/item.htm?id=534923831046","打开订单商品") -> 打开订单商品 | G30: M2*12[200只]镀镍 | H30: 200 | I30: 按打印模型及对应安装位置选择长度；每包数量是备料数量。 | J30: 85 | K30: 3.88
A31: 螺丝 | B31: M2.6×8 十字盘头平尾自攻螺丝 | C31: 铁镀镍 / 十字圆头 / 平尾自攻 / M2.6×8 | D31: 按模型对应孔位选用 | E31: 固万基官方旗舰店 | F31: =HYPERLINK("https://item.taobao.com/item.htm?id=534923831046","打开订单商品") -> 打开订单商品 | G31: M2.6*8[200只]镀镍 | H31: 200 | I31: 按打印模型及对应安装位置选择长度；每包数量是备料数量。 | J31: 89 | K31: 3.59

Sheet 订单匹配依据
A2: 相关订单匹配依据
A3: 源：订单数据.xlsx；仅保留本次采购相关的103条商品记录。
A4: 数量是订单拍数，不一定等于器件个数。每拍包装数量由商品款式单独解析。
A5: 商品金额按原字段抄录，不作为统一单价，不混算采购总价。重复/旧版购买保留作依据。
A6: 订单源行 | B6: 提交日期 | C6: 订单状态 | D6: 店铺 | E6: 商品名称（原文） | F6: 型号款式（原文） | G6: 商品数量(原值) | H6: 商品金额(元，原字段) | I6: 商品链接 | J6: 对应采购项 / 历史用途
A7: 4 | B7: 46306 | C7: 卖家已发货 | D7: 深圳市RTC电子 | E7: LSM6DSLTR LSM6DSOTR LSM6DSRTR LSM6DS3TR-C LSM6DSV16XTR LGA14 | F7: LSM6DSV16XTR | G7: 2 | H7: 5.75 | I7: =HYPERLINK("https://item.taobao.com/item.htm?id=640391703111","打开商品") -> 打开商品 | J7: 同款或历史购买记录
A8: 6 | B8: 46305 | C8: 卖家已发货 | D8: 永茂电子 | E8: AMP2.0间距2.0 179228 电池端子连接线 舵机线 镍片端子线 | F8: 200mm;1007/24#;3P;AMP2.0 | G8: 30 | H8: 0.9 | I8: =HYPERLINK("https://item.taobao.com/item.htm?id=825340808235","打开商品") -> 打开商品 | J8: 其他接口体系，按对应连接方案使用
A9: 23 | B9: 46293 | C9: 交易成功 | D9: zxin旗舰店 | E9: 2.54MM间距 双排贴片排母 2*3/4/5/6/8/10/15/20/40P | F9: 2*20P=5只 | G9: 1 | H9: 9.1 | I9: =HYPERLINK("https://item.taobao.com/item.htm?id=606745016341","打开商品") -> 打开商品 | J9: 同款或历史购买记录
A10: 24 | B10: 46293 | C10: 交易成功 | D10: 凯特森工具 | E10: 精密清洗套装纳米清洁海绵高效吸附洗板水手机主板芯片维修强去污 | F10: 海绵清洗剂实惠组合 | G10: 1 | H10: 14.16 | I10: =HYPERLINK("https://item.taobao.com/item.htm?id=1049340097483","打开商品") -> 打开商品 | J10: 洗板清洁套装
A11: 35 | B11: 46290 | C11: 交易成功 | D11: 安立信旗舰店 | E11: 安立信锡浆贴片焊接锡膏手机维修环保无铅高中低温焊锡膏针筒锡泥 | F11: 183℃中温有铅锡膏30G/支(常用款) 【送推杆/针头】 | G11: 1 | H11: 13.8 | I11: =HYPERLINK("https://item.taobao.com/item.htm?id=626569273184","打开商品") -> 打开商品 | J11: 183℃ 有铅锡膏针筒
A12: 36 | B12: 46290 | C12: 交易成功 | D12: 永茂电子 | E12: AMP2.0间距2.0 179228 电池端子线 端子连接线 电子线 镍片端子线 | F12: 100mm;1007/24#;3P;AMP2.0 | G12: 30 | H12: 0.9 | I12: =HYPERLINK("https://item.taobao.com/item.htm?id=825340808235","打开商品") -> 打开商品 | J12: 其他接口体系，按对应连接方案使用
A13: 43 | B13: 46282 | C13: 交易成功 | D13: 亚润五金专营店 | E13: 白光BK701D热风枪焊台二合一锡焊电烙铁数显恒温风枪可调温拆焊台 | F13: SBK701D旋钮款（气泵式/收藏送2支烙铁头） | G13: 1 | H13: 268 | I13: =HYPERLINK("https://item.taobao.com/item.htm?id=566089419587","打开商品") -> 打开商品 | J13: 热风枪焊台
A14: 50 | B14: 46282 | C14: 交易成功 | D14: 深圳市宏宸电子 | E14: 0603/1608贴片电容 1u1.5u2.2u3.3u4.7u6.8u10u15u22u33u47uF | F14: 0603 10uF ±10% X5R;10V | G14: 50 | H14: 0.06 | I14: =HYPERLINK("https://item.taobao.com/item.htm?id=630712731066","打开商品") -> 打开商品 | J14: C1608X5R1A106KT000E
A15: 52 | B15: 46282 | C15: 交易成功 | D15: 深圳市永芯泰电子企业店 | E15: 0603 0805 1206贴片电阻 10R 100R 1K 2K 4.7K 10K 100K 1M 欧 1% | F15: 22R/22欧;0603 1%（100个） | G15: 1 | H15: 1.46 | I15: =HYPERLINK("https://item.taobao.com/item.htm?id=947267344247","打开商品") -> 打开商品 | J15: TH1之前调试的22Ω电阻订单，当前采购采用原村田PTC
A16: 53 | B16: 46282 | C16: 交易成功 | D16: 深圳市永芯泰电子企业店 | E16: 0603 0805 1206贴片电阻 10R 100R 1K 2K 4.7K 10K 100K 1M 欧 1% | F16: 10K;0603 1%（100个） | G16: 1 | H16: 1.42 | I16: =HYPERLINK("https://item.taobao.com/item.htm?id=947267344247","打开商品") -> 打开商品 | J16: 同款或历史购买记录
A17: 56 | B17: 46282 | C17: 交易成功 | D17: 深圳市永芯泰电子企业店 | E17: 0603 0805 1206贴片电阻 10R 100R 1K 2K 4.7K 10K 100K 1M 欧 1% | F17: 100K;0603 1%（100个） | G17: 1 | H17: 1.46 | I17: =HYPERLINK("https://item.taobao.com/item.htm?id=947267344247","打开商品") -> 打开商品 | J17: RC0603FR-07100KL
A18: 76 | B18: 46279 | C18: 交易成功 | D18: 凯特森工具 | E18: 无铅环保吸锡带焊盘清洁维修残留除锡渣吸锡线PCB电路板手机主板 | F18: 原装吸锡〖宽1.5mm长1.5米〗[X-100型1515] | G18: 1 | H18: 3.91 | I18: =HYPERLINK("https://item.taobao.com/item.htm?id=972313702890","打开商品") -> 打开商品 | J18: 吸锡带
A19: 77 | B19: 46279 | C19: 交易成功 | D19: 信容芯旗舰店 | E19: 信容芯 SH1.0转杜邦公/杜邦母2P3P4P5P6P7P8P9P10P 28AWG渡锡铜线 | F19: 0.2m;1.0-4P转杜邦母（5条） | G19: 1 | H19: 4.56 | I19: =HYPERLINK("https://item.taobao.com/item.htm?id=895049863252","打开商品") -> 打开商品 | J19: SH1.0 4P 转杜邦母线
A20: 78 | B20: 46279 | C20: 交易成功 | D20: 深圳市宏宸电子 | E20: 0603/1608贴片电容 1u1.5u2.2u3.3u4.7u6.8u10u15u22u33u47uF | F20: 0603 1uF ±10% X7R;50V | G20: 100 | H20: 0.03 | I20: =HYPERLINK("https://item.taobao.com/item.htm?id=630712731066","打开商品") -> 打开商品 | J20: CC0603KRX5R9BB105, CL10A105KB8NNNC
A21: 79 | B21: 46279 | C21: 交易成功 | D21: 深圳市宏宸电子 | E21: 0603/1608贴片电容 100n120n150n180n220n270nF 104 154 224 274K | F21: 0603 100nF ±10% X7R;50V;100个 | G21: 1 | H21: 1.98 | I21: =HYPERLINK("https://item.taobao.com/item.htm?id=731471380840","打开商品") -> 打开商品 | J21: CC0603KRX7R9BB104, CL10B104JB8NNNC
A22: 80 | B22: 46279 | C22: 交易成功 | D22: 深圳市永芯泰电子企业店 | E22: 0603 0805 1206贴片电阻 10R 100R 1K 2K 4.7K 10K 100K 1M 欧 1% | F22: 10K;0603 1%（100个） | G22: 1 | H22: 1.42 | I22: =HYPERLINK("https://item.taobao.com/item.htm?id=947267344247","打开商品") -> 打开商品 | J22: RC0603FR-0710KL
A23: 81 | B23: 46279 | C23: 交易成功 | D23: 启色数码旗舰店 | E23: EH2.5MM直针插座 弯针 胶壳 间距2.54MM接插件 2P 3P 4P 5P 6P | F23: EH2.5MM 3P胶壳（50个） | G23: 1 | H23: 2.8 | I23: =HYPERLINK("https://item.taobao.com/item.htm?id=832569969546","打开商品") -> 打开商品 | J23: EH 3P 母壳
A24: 82 | B24: 46279 | C24: 交易成功 | D24: 启色数码旗舰店 | E24: EH2.5MM直针插座 弯针 胶壳 间距2.54MM接插件 2P 3P 4P 5P 6P | F24: EH2.5MM 2P胶壳（50个） | G24: 1 | H24: 2.2 | I24: =HYPERLINK("https://item.taobao.com/item.htm?id=832569969546","打开商品") -> 打开商品 | J24: EH 2P 母壳
A25: 83 | B25: 46279 | C25: 交易成功 | D25: 启色数码旗舰店 | E25: EH2.5MM直针插座 弯针 胶壳 间距2.54MM接插件 2P 3P 4P 5P 6P | F25: EH2.5MM 端子（100个） | G25: 1 | H25: 3.5 | I25: =HYPERLINK("https://item.taobao.com/item.htm?id=832569969546","打开商品") -> 打开商品 | J25: EH 压接端子
A26: 91 | B26: 46276 | C26: 交易成功 | D26: 深圳市RTC电子 | E26: LSM6DSLTR LSM6DSOTR LSM6DSRTR LSM6DS3TR-C LSM6DSV16XTR LGA14 | F26: LSM6DSV16XTR | G26: 2 | H26: 5.75 | I26: =HYPERLINK("https://item.taobao.com/item.htm?id=640391703111","打开商品") -> 打开商品 | J26: LSM6DSV16XTR
A27: 92 | B27: 46276 | C27: 交易成功 | D27: 都会明武电子 | E27: VL53L5X V2 TOF宽视场飞行时间多区域激光测距传感器模块VL53L5CX | F27: VL53L5X V2模块配盖片 | G27: 1 | H27: 49.5 | I27: =HYPERLINK("https://item.taobao.com/item.htm?id=737603917521","打开商品") -> 打开商品 | J27: 8×8 ToF 测距模块
A28: 93 | B28: 46276 | C28: 交易成功 | D28: 一芯向上电子 | E28: SI2300 2301 2302 2303 2304 2305 2306 2307 2308 2312DS 2309 | F28: SI2312DS（AE9T）N沟道（20只） | G28: 1 | H28: 3 | I28: =HYPERLINK("https://item.taobao.com/item.htm?id=909264246006","打开商品") -> 打开商品 | J28: SI2312CDS-T1-GE3
A29: 94 | B29: 46276 | C29: 交易成功 | D29: 深圳市乐桥微科技 | E29: 全新原装BAT54SW BAT54S SOT-323 丝印44t 肖特基贴片三极管 20只 | F29: BAT54SW 印字44t（20只） | G29: 1 | H29: 4.5 | I29: =HYPERLINK("https://item.taobao.com/item.htm?id=793455311175","打开商品") -> 打开商品 | J29: BAT54SW,115
A30: 95 | B30: 46276 | C30: 交易成功 | D30: 贤辉亿芯 | E30: PTC热敏电阻 0603 100R 47R 33R 220R 470R 过电流热保护RPG18BB | F30: 100R PRG18BB101MB1RB | G30: 10 | H30: 0.7 | I30: =HYPERLINK("https://item.taobao.com/item.htm?id=582129955778","打开商品") -> 打开商品 | J30: TH1原村田PRG18BB101MB1RB，100Ω PTC；当前采购款式
A31: 96 | B31: 46276 | C31: 交易成功 | D31: 优好电子 | E31: 0402 0603 0805 1206 1210贴片电容22UF 226K 226P X5R 10% 50V | F31: 22UF 226K 10% X5R;10V;0603=100个 | G31: 1 | H31: 3.5 | I31: =HYPERLINK("https://item.taobao.com/item.htm?id=993202872551","打开商品") -> 打开商品 | J31: GRM188R61A226ME15D
A32: 100 | B32: 46275 | C32: 交易成功 | D32: 瑞莎计算机(深圳)有限公司 | E32: 瑞莎 Radxa 迷你主板 ZERO 3W RK3566 四核CPU WiFi6 Microduck | F32: 2GB RAM 无 eMMC 带排针[【Microduck 原版主板】] | G32: 1 | H32: 309 | I32: =HYPERLINK("https://item.taobao.com/item.htm?id=763812025816","打开商品") -> 打开商品 | J32: Radxa ZERO 3W
A33: 103 | B33: 46274 | C33: 交易成功 | D33: 深圳市优信电子科技有限公司 | E33: 3525腔体-4Ω3W/8Ω2W BOX蓝牙音响扬声器安防喇叭 带1.25端子 | F33: 3525腔体-4Ω3W/喇叭 | G33: 1 | H33: 3.08 | I33: =HYPERLINK("https://item.taobao.com/item.htm?id=683920556900","打开商品") -> 打开商品 | J33: 扬声器
A34: 105 | B34: 46274 | C34: 交易成功 | D34: 阔筹旗舰店 | E34: 防静电润轴镊子机械键盘短接镊子尖头弯头圆头精密电子元器件焊接 | F34: 防静电ESD-10【短尖头】 | G34: 1 | H34: 1.98 | I34: =HYPERLINK("https://item.taobao.com/item.htm?id=979077591318","打开商品") -> 打开商品 | J34: 防静电镊子
A35: 106 | B35: 46274 | C35: 交易成功 | D35: 中山市宝工电子有限公司 | E35: 厂家直销 有铅锡膏 6337锡膏 SMT贴片锡浆 LED锡膏 焊锡膏183℃ | F35: 手机维修焊锡膏50g | G35: 1 | H35: 20.99 | I35: =HYPERLINK("https://item.taobao.com/item.htm?id=19606507546","打开商品") -> 打开商品 | J35: 183℃ 有铅锡膏
A36: 107 | B36: 46274 | C36: 交易成功 | D36: 皓越科技smt激光钢网 | E36: 手帖打样SMT钢网精密制造PCB模板贴片锡膏红胶LED钢网小钢片 | F36: 10*10cm | G36: 1 | H36: 8.6 | I36: =HYPERLINK("https://item.taobao.com/item.htm?id=851008959999","打开商品") -> 打开商品 | J36: 定制贴片钢网
A37: 117 | B37: 46272 | C37: 交易成功 | D37: 启色数码旗舰店 | E37: EH2.5MM直针插座 弯针 胶壳 间距2.54MM接插件 2P 3P 4P 5P 6P | F37: EH2.5MM 3P直针座（50个） | G37: 1 | H37: 3 | I37: =HYPERLINK("https://item.taobao.com/item.htm?id=832569969546","打开商品") -> 打开商品 | J37: B3B-EH-A(LF)(SN)
A38: 118 | B38: 46272 | C38: 交易成功 | D38: 启色数码旗舰店 | E38: EH2.5MM直针插座 弯针 胶壳 间距2.54MM接插件 2P 3P 4P 5P 6P | F38: EH2.5MM 2P直针座（50个） | G38: 1 | H38: 2.5 | I38: =HYPERLINK("https://item.taobao.com/item.htm?id=832569969546","打开商品") -> 打开商品 | J38: B2B-EH-A(LF)(SN)
A39: 119 | B39: 46272 | C39: 交易成功 | D39: 启色数码旗舰店 | E39: XC6206P182MR 丝印65K5 SOT-23 1.8V 300MA 贴片稳压芯片 (20个) | F39: XC6206P182MR 65K5 SOT-23 (20个) | G39: 1 | H39: 1.8 | I39: =HYPERLINK("https://item.taobao.com/item.htm?id=762173333947","打开商品") -> 打开商品 | J39: XC6206P182MR
A40: 121 | B40: 46272 | C40: 交易成功 | D40: 稳泊仕旗舰店 | E40: MMBT3904 1AM MMBT3906 2A SOT-23贴片晶体功率三极管NPN PNP | F40: MMBT3906 丝印2A SOT-23(50个) | G40: 1 | H40: 1.77 | I40: =HYPERLINK("https://item.taobao.com/item.htm?id=944306254140","打开商品") -> 打开商品 | J40: MMBT3906
A41: 122 | B41: 46272 | C41: 交易成功 | D41: 稳泊仕旗舰店 | E41: SOD-323稳压管BZT52C5V1S 2.4V3.3V4.7V5.1V10V12V15V24V30V33V47 | F41: BZT52C5V1S W8 SOD-323 (50个) | G41: 1 | H41: 1.53 | I41: =HYPERLINK("https://item.taobao.com/item.htm?id=943185002457","打开商品") -> 打开商品 | J41: BZT52C5V1S-7-F
...

Sheet 制作工具与耗材
A2: 制作工具与耗材
A3: 焊接、回流、贴装、清洁和调试用品。已有工具可继续使用。
A4: 钢网按对应Gerber定制；锡膏包装按习惯选择。
A5: 订单商品金额按一拍记录；包装或购入数量包含备料。金额依据订单数据.xlsx。
A6: 类别 | B6: 商品 / 用品 | C6: 具体规格 | D6: 用量或购买条件 | E6: 订单店铺 | F6: 商品链接 | G6: 订单原款式 | H6: 每拍含量 | I6: 购买说明 | J6: 订单源行 | K6: 订单商品金额 / 拍(元)
A7: 烧录工具 | B7: ST-LINK V2 | C7: STM32 仿真器，订单进口芯片版本 | D7: 已有可不买 | E7: zazr旗舰店 | F7: =HYPERLINK("https://item.taobao.com/item.htm?id=581798084270","打开订单商品") -> 打开订单商品 | G7: ST-LINK V2 仿真器 进口芯片软件可升级版本（颜色随机发）1个 | H7: 1 | I7: 用于 IMU STM32 的 SWD 烧录。 | J7: 154 | K7: 9.84
A8: 制作耗材 | B8: 定制贴片钢网 | C8: 10×10cm 规格 | D8: HAT、IMU按各自Gerber定制 | E8: 皓越科技smt激光钢网 | F8: =HYPERLINK("https://item.taobao.com/item.htm?id=851008959999","打开订单商品") -> 打开订单商品 | G8: 10*10cm | H8: 1 | I8: 这是定制商品链接，付款后需提供对应钢网文件；订单没有保存具体开孔内容。 | J8: 107 | K8: 8.6
A9: 制作耗材 | B9: 183℃ 有铅锡膏 | C9: 63/37，订单50g罐装 | D9: 已有可不买 | E9: 中山市宝工电子有限公司 | F9: =HYPERLINK("https://item.taobao.com/item.htm?id=19606507546","打开订单商品") -> 打开订单商品 | G9: 手机维修焊锡膏50g | H9: 1 | I9: 与家庭回流工艺对应；按实际工具和温度流程使用。 | J9: 106 | K9: 20.99
A10: 制作耗材 | B10: 183℃ 有铅锡膏针筒 | C10: 30g / 针筒 / 含推杆针头 | D10: 与上一条按习惯选用 | E10: 安立信旗舰店 | F10: =HYPERLINK("https://item.taobao.com/item.htm?id=626569273184","打开订单商品") -> 打开订单商品 | G10: 183℃中温有铅锡膏30G/支(常用款) 【送推杆/针头】 | H10: 1 | I10: 与罐装锡膏是另一包装方案，不需要两种都买。 | J10: 35 | K10: 13.8
A11: 制作工具 | B11: 防静电镊子 | C11: ESD-10 短尖头 | D11: 已有可不买 | E11: 阔筹旗舰店 | F11: =HYPERLINK("https://item.taobao.com/item.htm?id=979077591318","打开订单商品") -> 打开订单商品 | G11: 防静电ESD-10【短尖头】 | H11: 1 | I11: 用于贴装。 | J11: 105 | K11: 1.98
A12: 制作工具 | B12: 恒温加热台 | C12: 150×100mm / 定时 / 3组温度预设 | D12: 已有可不买 | E12: 汉邦电子 | F12: =HYPERLINK("https://item.taobao.com/item.htm?id=956985590887","打开订单商品") -> 打开订单商品 | G12: 【150*100mm】智能定时/3组温度预设 | H12: 1 | I12: 订单记录对应家庭回流工具。 | J12: 211 | K12: 188
A13: 返修工具 | B13: 热风枪焊台 | C13: SBK701D旋钮款（气泵式） | D13: 按返修需求选用 | E13: 亚润五金专营店 | F13: =HYPERLINK("https://item.taobao.com/item.htm?id=566089419587","打开订单商品") -> 打开订单商品 | G13: SBK701D旋钮款（气泵式/收藏送2支烙铁头） | H13: 1 | I13: 可用于返修；不计入 PCB BOM。 | J13: 43 | K13: 268
A14: 返修耗材 | B14: 吸锡带 | C14: 1.5mm宽 / 1.5m / X-100型1515 | D14: 按返修需求选用 | E14: 凯特森工具 | F14: =HYPERLINK("https://item.taobao.com/item.htm?id=972313702890","打开订单商品") -> 打开订单商品 | G14: 原装吸锡〖宽1.5mm长1.5米〗[X-100型1515] | H14: 1 | I14: 用于焊盘清理。 | J14: 76 | K14: 3.91
A15: 制作耗材 | B15: 助焊膏 | C15: YG-336 / 10g 针筒 | D15: 已有可不买 | E15: YGTCTECH永冠同创 | F15: =HYPERLINK("https://item.taobao.com/item.htm?id=744370287305","打开订单商品") -> 打开订单商品 | G15: YG-336环保无铅BGA针筒助焊膏10g | H15: 1 | I15: 原订单款式；不计入 PCB BOM。 | J15: 220 | K15: 3.28
A16: 清洁耗材 | B16: 洗板清洁套装 | C16: 海绵清洗剂组合 | D16: 已有可不买 | E16: 凯特森工具 | F16: =HYPERLINK("https://item.taobao.com/item.htm?id=1049340097483","打开订单商品") -> 打开订单商品 | G16: 海绵清洗剂实惠组合 | H16: 1 | I16: 原订单未提供清洗剂成分，不将其列为电气材料。 | J16: 24 | K16: 14.16
A17: 舵机调试工具 | B17: 飞特 USB 调试转接板 | C17: FE-URT2-C001 | D17: 烧录、配置及调试时选用 | E17: 深圳飞特舵机工厂店 | F17: =HYPERLINK("https://item.taobao.com/item.htm?id=1078248851201","打开订单商品") -> 打开订单商品 | G17: FE-URT2-C001 | H17: 1 | I17: 调试工具，按FE-URT2-C001选项购买。 | J17: 169 | K17: 45
A18: 焊接工具 | B18: 安立信937A 数显焊台 | C18: 937A升级数显 / 套餐二 | D18: 已有可省 | E18: 安立信旗舰店 | F18: =HYPERLINK("https://item.taobao.com/item.htm?id=588102758150","打开订单商品") -> 打开订单商品 | G18: 安立信937A升级数显（套餐二） | H18: 1 | I18: 订单购买的电烙铁焊台，用于手工焊接。 | J18: 189 | K18: 106.68
A19: 烙铁头 | B19: 900M-T-LI 长尖头 | C19: 900M-T-LI | D19: 按焊接习惯选用 | E19: 白光安泰信品牌经营店 | F19: =HYPERLINK("https://item.taobao.com/item.htm?id=567201709691","打开订单商品") -> 打开订单商品 | G19: 900M-T-LI长尖头 | H19: 1 | I19: 按900M-T-LI长尖头款式购买。 | J19: 39 | K19: 3.63
A20: 烙铁头 | B20: 900M-T-SK 小刀头 | C20: 900M-T-SK | D20: 按焊接习惯选用 | E20: 白光安泰信品牌经营店 | F20: =HYPERLINK("https://item.taobao.com/item.htm?id=567201709691","打开订单商品") -> 打开订单商品 | G20: 900M-T-SK小刀头 | H20: 1 | I20: 按900M-T-SK小刀头款式购买。 | J20: 40 | K20: 3.3
A21: 制作耗材 | B21: 183℃ 有铅锡膏 10g 针筒 | C21: 183℃熔点 / 有铅 / 10g / 配杆针 | D21: 按包装习惯选购 | E21: OLK唐宏五金工具店 | F21: =HYPERLINK("https://item.taobao.com/item.htm?id=621018369847","打开订单商品") -> 打开订单商品 | G21: 183℃熔点有铅锡浆10g+杆针 | H21: 1 | I21: 与50g罐装、30g针筒是不同包装选择。 | J21: 214 | K21: 4.69

Sheet 制作成本
A2: HAT 与 IMU 制作成本
A3: 按历史订单实付（含原运费）分摊，单板材料与整包采购分别计算。配件、舵机和工具另见采购表。
A4: HAT块数 | B4: =合并采购清单!B4 -> 1 | C4: IMU块数 | D4: =合并采购清单!D4 -> 1
A5: PCB每批金额(元) | B5: 20 | C5: PCB每批张数 | D5: 5 | E5: 钢网每张(元) | F5: 12
A7: 单板材料成本 | B7: HAT | C7: IMU | D7: 合计
A8: 板上元器件（含历史运费分摊） | B8: =SUM(I29:I72) -> 16.724905 | C8: =SUM(J29:J72) -> 12.333632 | D8: =SUM(B8:C8) -> 29.058537
A9: PCB：有免费券 | B9: 0 | C9: 0 | D9: =SUM(B9:C9) -> 0
A10: 有券：材料成本 | B10: =B8+B9 -> 16.724905 | C10: =C8+C9 -> 12.333632 | D10: =D8+D9 -> 29.058537
A11: PCB：无券，折算单板 | B11: =$B$5/$D$5*$B$4 -> 4 | C11: =$B$5/$D$5*$D$4 -> 4 | D11: =SUM(B11:C11) -> 8
A12: 无券：材料成本 | B12: =B8+B11 -> 20.724905 | C12: =C8+C11 -> 16.333632 | D12: =D8+D11 -> 37.058537
A14: 首次按包装采购（商品金额，运费另计）
